<?xml version="1.0"?>
<robot xmlns:xacro="http://ros.org/wiki/xacro">

  <xacro:include filename="$(find relax_urdf)/urdf/parts/common_base_properties.urdf.xacro" />
  <xacro:include filename="$(find relax_urdf)/urdf/gazebo/imu.gazebo.urdf.xacro" />
  <xacro:include filename="$(find relax_urdf)/urdf/gazebo/mir.gazebo.xacro" />
  <xacro:include filename="$(find relax_urdf)/urdf/parts/mir.transmission.xacro" />
  <xacro:include filename="$(find relax_urdf)/urdf/parts/sick_s300.urdf.xacro" />

  <xacro:include filename="$(find relax_urdf)/urdf/parts/wheels.urdf.xacro" />
  
  <xacro:property name="laser_dx" value="0.315" />
  <xacro:property name="laser_dy" value="0.205" />
  
  <xacro:property name="laser_dz" value="0.1914" />


  <xacro:macro name="mir" params="prefix">
    <link name="${prefix}base_footprint" />

    <joint name="${prefix}base_joint" type="fixed">
      <parent link="${prefix}base_footprint" />
      <child link="${prefix}base_link" />
      <origin xyz="0 0 0" rpy="0 0 0" />
    </joint>

    <link name="${prefix}base_link">
      <xacro:box_inertial mass="${mir_base_mass}" x="${mir_base_inertial_x_length}" y="${mir_base_inertial_y_length}" z="${mir_base_inertial_z_length}">
        <origin xyz="${mir_base_inertial_x + mir_act_wheel_dx} ${mir_base_inertial_y} ${mir_base_inertial_z}" rpy="0 0 0" />
      </xacro:box_inertial>
      <visual>
        <origin xyz="${mir_act_wheel_dx} 0 0" rpy="0 0 0" />
        <geometry>
          <mesh filename="package://relax_urdf/meshes/mesh_base_revised.stl" scale="0.001 0.001 0.001"/>
        </geometry>
        <xacro:insert_block name="material_dark_grey" />
      </visual>
      <collision>
        <origin xyz="${mir_act_wheel_dx} 0 0" rpy="0 0 0" />
        <geometry>
          <mesh filename="package://relax_urdf/meshes/mesh_base_revised.stl"  scale="0.001 0.001 0.001"/>
        </geometry>
      </collision>
    </link>
    <gazebo reference="${prefix}base_link">
      <material>Gazebo/DarkGrey</material>
    </gazebo>

    <!-- IMU -->
    <joint name="${prefix}base_link_to_imu_joint" type="fixed">
      <parent link="${prefix}base_link" />
      <child link="${prefix}imu_link" />
      <origin xyz="0.0 0.0 0.25" rpy="0 0 0" />  <!-- same as real MiR -->
    </joint>

    <link name="${prefix}imu_link" />

    <xacro:imu_gazebo link="${prefix}imu_link" imu_topic="imu_data" update_rate="50.0" />

    <!-- Create an alias for imu_link. This is necessary because the real MiR's
         TF has imu_link, but the imu_data topic is published in the imu_frame
         frame. -->
    <joint name="${prefix}imu_link_to_imu_frame_joint" type="fixed">
      <parent link="${prefix}imu_link" />
      <child link="${prefix}imu_frame" />
      <origin xyz="0 0 0" rpy="0 0 0" />
    </joint>

    <link name="${prefix}imu_frame" />

    <!-- Laser scanners -->
    <joint name="${prefix}base_link_to_front_laser_joint" type="fixed">
      <parent link="${prefix}base_link" />
      <child link="${prefix}front_laser_link" />
      <origin xyz="${laser_dx + mir_act_wheel_dx} ${laser_dy} ${laser_dz}" rpy="0.0 0.0 ${0.25 * pi}" />
    </joint>
    <xacro:sick_s300 prefix="${prefix}" link="front_laser_link" topic="f_scan" />

    <joint name="${prefix}base_link_to_back_laser_joint" type="fixed">
      <parent link="${prefix}base_link" />
      <child link="${prefix}back_laser_link" />
      <origin xyz="${-laser_dx + mir_act_wheel_dx} ${-laser_dy} ${laser_dz}" rpy="0.0 0.0 ${-0.75 * pi}" />
    </joint>

    <xacro:sick_s300 prefix="${prefix}" link="back_laser_link" topic="b_scan" />

    <!-- Ultrasound sensors -->
    <joint name="${prefix}us_1_joint" type="fixed">   <!-- right ultrasound -->
      <parent link="${prefix}base_link" />
      <child link="${prefix}us_1_frame" />
      <origin xyz="0.45 -0.12 0.16 " rpy="0 0 0" />  <!-- from visually matching to the mesh of the MiR -->
    </joint>

    <link name="${prefix}us_1_frame" />

    <joint name="${prefix}us_2_joint" type="fixed">   <!-- left ultrasound -->
      <parent link="${prefix}base_link" />
      <child link="${prefix}us_2_frame" />
      <origin xyz="0.45 0.12 0.16 " rpy="0 0 0" />  <!-- from visually matching to the mesh of the MiR -->
    </joint>

    <link name="${prefix}us_2_frame" />

    <!-- wheels MANUALLY DONE FOR HIGH LEVEL CONTROL -->
    
    <joint name="left_wheel_joint" type="revolute">
      <origin rpy="0 0 0" xyz="0.0 0.2015 0.1"/>
      <parent link="base_link"/>
      <child link="left_wheel_link"/>
      <axis xyz="0 0 1"/>
      <limit upper="1e9" lower="-1e9" effort="2" velocity="2.0"/>
    </joint>
    <link name="left_wheel_link">
    <inertial>
      <mass value="1.0"/>
      <origin rpy="0 0 0" xyz="0 0 0"/>
      <inertia ixx="0.0026203322852000007" ixy="0.0" ixz="0.0" iyy="0.0026203322852000007" iyz="0.0" izz="0.005000000000000001"/>
    </inertial>
    <visual>
      <origin rpy="1.5707963267948966 0 0" xyz="0 0 0"/>
      <geometry>
        <cylinder length="0.038" radius="0.1"/>
      </geometry>
      <material name="black">
        <color rgba="0.1 0.1 0.1 1"/>
      </material>
    </visual>
    <collision>
      <origin rpy="1.5707963267948966 0 0" xyz="0 0 0"/>
      <geometry>
        <cylinder length="0.038" radius="0.1"/>
      </geometry>
    </collision>
  </link>
  <gazebo reference="left_wheel_link">
    <material>Gazebo/FlatBlack</material>
  </gazebo>


  <joint name="fl_caster_rotation_joint" type="prismatic">
    <origin rpy="0 0 0" xyz="0.299215 0.188 0.1565"/>
    <parent link="base_link"/>
    <child link="fl_caster_rotation_link"/>
    <axis xyz="1 0 0"/>
    <limit upper="1e9" lower="-1e9" effort="2" velocity="2.0"/>
    <dynamics damping="0.01" friction="0.0"/>
  </joint>
  <link name="fl_caster_rotation_link">
    <inertial>
      <!-- <origin xyz="0 0 -0.042500000044" rpy="${0.5 * pi} ${24 * deg_to_rad} ${1.5 * pi}" /> -->
      <origin rpy="0 0 0" xyz="0 0 -0.042500000044"/>
      <!-- ${24 * deg_to_rad} 0 ${0.5 * pi} -->
      <mass value="0.3097539019"/>
      <inertia ixx="0.0005844517978" ixy="0" ixz="0" iyy="0.00052872551237" iyz="0" izz="0.00017923555074"/>
    </inertial>
    <visual>
      <origin rpy="0 0 0" xyz="0 0 0"/>
      <geometry>
        <mesh filename="package://relax_urdf/meshes/caster_wheel_base.stl"/>
      </geometry>
      <material name="black">
        <color rgba="0.1 0.1 0.1 1"/>
      </material>
    </visual>
    <collision>
      <origin rpy="0 0 0" xyz="0 0 0"/>
      <geometry>
        <mesh filename="package://relax_urdf/meshes/caster_wheel_base.stl"/>
      </geometry>
    </collision>
  </link>
  <gazebo reference="fl_caster_rotation_link">
    <material>Gazebo/FlatBlack</material>
  </gazebo>

  <joint name="fl_caster_wheel_joint" type="fixed">
    <origin rpy="0 0 0" xyz="-0.0382 0 -0.094"/>
    <parent link="fl_caster_rotation_link"/>
    <child link="fl_caster_wheel_link"/>
    <axis xyz="0 1 0"/>
    <limit upper="1e9" lower="-1e9" effort="2" velocity="2.0"/>
  </joint>
  <link name="fl_caster_wheel_link">
    <inertial>
      <mass value="1.0"/>
      <origin rpy="0 0 0" xyz="0 0 0"/>
      <inertia ixx="0.001061895408575" ixy="0.0" ixz="0.0" iyy="0.001061895408575" iyz="0.0" izz="0.001953125"/>
    </inertial>
    <visual>
      <origin rpy="1.57 0 0" xyz="0 0 0"/>
      <!--${pi/2} 0 0 -->
      <geometry>
        <cylinder length="0.032" radius="0.0625"/>
      </geometry>
      <material name="black">
        <color rgba="0.1 0.1 0.1 1"/>
      </material>
    </visual>
    <collision>
      <origin rpy="1.57 0 0" xyz="0 0 0"/>
      <!--${pi/2} 0 0 -->
      <geometry>
        <cylinder length="0.032" radius="0.0625"/>
      </geometry>
    </collision>
  </link>
  <gazebo reference="fl_caster_wheel_link">
    <material>Gazebo/FlatBlack</material>
  </gazebo>

    <xacro:actuated_wheel prefix="${prefix}" locationprefix="right" locationright="1"/>
    <xacro:caster_wheel prefix="${prefix}" locationprefix="fr" locationright="1" wheel_base_dx="${mir_front_caster_wheel_base_dx + mir_act_wheel_dx}"/>
    <xacro:caster_wheel prefix="${prefix}" locationprefix="bl" locationright="-1" wheel_base_dx="${-mir_back_caster_wheel_base_dx + mir_act_wheel_dx}"/>
    <xacro:caster_wheel prefix="${prefix}" locationprefix="br" locationright="1" wheel_base_dx="${-mir_back_caster_wheel_base_dx + mir_act_wheel_dx}"/>

    <joint name="${prefix}base_link_surface_joint" type="fixed">
      <origin xyz="${mir_act_wheel_dx} 0 0.352" rpy="0 0 0" />
      <parent link="${prefix}base_link" />
      <child link="${prefix}surface" />
      <axis xyz="0 0 1" />
    </joint>

    <link name="${prefix}surface"/>

    <xacro:mir_wheel_transmissions prefix="${prefix}"/>

    <!-- set the gazebo friction parameters for the wheels -->
    <xacro:set_all_wheel_frictions prefix="${prefix}"/>

    <xacro:p3d_base_controller prefix="${prefix}" />
  </xacro:macro>
</robot>
