<?xml version="1.0"?>
<robot xmlns:xacro="http://ros.org/wiki/xacro">

<!-- links -->
<link name ="mobile_base_link">  <!-- mobile base link -->
    <inertial>
      <origin xyz="0.0 0.0 0.0" rpy="0 0 0"/>
      <mass value="10.0"/>
      <inertia ixx="1.7" ixy="0.0" ixz="0.0" iyy="1.7" iyz="0.0" izz="1.7" />
    </inertial>
    <visual>
      <origin xyz="0 0 0" rpy="0 0 0"/>
      <geometry name="mobile_base_link_visual">
        <mesh filename="package://relax_urdf/meshes/mir_base.stl" scale="0.001 0.001 0.001" />
      </geometry>
      <material name="dark"/>
    </visual>
    <collision>
      <origin xyz="0 0 0" rpy="0 0 0"/>
      <geometry name="mobile_base_link_collision">
        <mesh filename="package://relax_urdf/meshes/mir_base.stl" scale="0.001 0.001 0.001" />
      </geometry>             
    </collision>
</link> 

<link name ="left_wheel">
    <inertial>
      <origin xyz="0.0 0.0 0.0" rpy="0 0 0"/>
      <mass value="1.0"/>
      <inertia ixx="0.17" ixy="0.0" ixz="0.0" iyy="0.17" iyz="0.0" izz="0.17" />
    </inertial>
    <visual>
      <origin xyz="0 0 0" rpy="0 0 0"/>
      <geometry name="mobile_base_link_visual">
        <mesh filename="package://relax_urdf/meshes/mesh_left_wheel.stl" scale="0.001 0.001 0.001" />
      </geometry>
      <material name="dark"/>
    </visual>
    <collision>
      <origin xyz="0 0 0" rpy="0 0 0"/>
      <geometry name="mobile_base_link_collision">
        <mesh filename="package://relax_urdf/meshes/mir_base.stl" scale="0.001 0.001 0.001" />
      </geometry>             
    </collision>
</link> 

<link name ="right_wheel">
    <inertial>
      <origin xyz="0.0 0.0 0.0" rpy="0 0 0"/>
      <mass value="1.0"/>
      <inertia ixx="0.17" ixy="0.0" ixz="0.0" iyy="0.17" iyz="0.0" izz="0.17" />
    </inertial>
    <visual>
      <origin xyz="0 0 0" rpy="0 0 0"/>
      <geometry name="mobile_base_link_visual">
        <mesh filename="package://relax_urdf/meshes/mesh_left_wheel.stl" scale="0.001 0.001 0.001" />
      </geometry>
      <material name="dark"/>
    </visual>
    <collision>
      <origin xyz="0 0 0" rpy="0 0 0"/>
      <geometry name="mobile_base_link_collision">
        <mesh filename="package://relax_urdf/meshes/mir_base.stl" scale="0.001 0.001 0.001" />
      </geometry>             
    </collision>
</link> 


<joint name="j_left_wheel" type="continuous">
	<parent link="mobile_base_link"/>
	<child link="left_wheel"/>
    <origin xyz="-0.00448719 0.25 0.09" rpy="0 0 0"/>
	<axis xyz="0 1 0"/>
   <limit  effort="35" velocity="20"/>
</joint>

<joint name="j_right_wheel" type="continuous">
	<parent link="mobile_base_link"/>
	<child link="right_wheel"/>
	<origin xyz="-0.00448719 -0.25 0.09" rpy="0 0 0"/>
	<axis xyz="0 1 0"/>
   <limit  effort="35" velocity="20"/>
</joint>

</robot>
