<?xml version="1.0" ?>
<!-- =================================================================================== -->
<!-- |    This document was autogenerated by xacro from relax_arm.urdf.xacro           | -->
<!-- |    EDITING THIS FILE BY HAND IS NOT RECOMMENDED                                 | -->
<!-- =================================================================================== -->
<robot name="relax">
  <!-- ************SELECT PARTS*************-->
  <!-- *************************************-->
  <!-- color -->
  <material name="darkblue">
    <color rgba="0.0 0.3 0.9 1"/>
  </material>
  <material name="dark">
    <color rgba="0.1 0.1 0.1 1"/>
  </material>
  <!-- ARM -->
  <!-- ARM -->
  <!-- ARM -->
  <!-- ARM -->
  <!-- links -->
  <link name="relax_arm1_link1">
    <!-- link 1 -->
    <inertial>
      <origin xyz="-0.0018991406 0.022645162 0.16741297"/>
      <mass value="6.2381702"/>
      <inertia ixx="0.065816037" ixy="-0.00011791629" ixz="-4.0067927e-05" iyy="0.057828314" iyz="-0.011584403" izz="0.01940196"/>
    </inertial>
    <visual>
      <origin rpy="0 0 0" xyz="0 0 0"/>
      <geometry name="relax_link1_visual">
        <mesh filename="package://relax_urdf/meshes/mesh_link1.stl" scale="0.001 0.001 0.001"/>
      </geometry>
      <material name="darkblue"/>
    </visual>
    <collision>
      <origin rpy="0 0 0" xyz="0 0 0"/>
      <geometry name="relax_link1_collision">
        <mesh filename="package://relax_urdf/meshes/mesh_link1.stl" scale="0.001 0.001 0.001"/>
      </geometry>
    </collision>
  </link>
  <link name="relax_arm1_link2">
    <!-- link 2 -->
    <inertial>
      <origin xyz="-3.1494342e-05 -0.20005579 -0.0057041875"/>
      <mass value="2.601371"/>
      <inertia ixx="0.064570453" ixy="-0.00019926537999999998" ixz="-1.6866045999999998e-06" iyy="0.0051512542" iyz="-2.9627309e-06" izz="0.06672465300000001"/>
    </inertial>
    <visual>
      <origin rpy="0 0 0" xyz="0 0 0"/>
      <geometry name="relax_link2_visual">
        <mesh filename="package://relax_urdf/meshes/mesh_link2.stl" scale="0.001 0.001 0.001"/>
      </geometry>
      <material name="dark"/>
    </visual>
    <collision>
      <origin rpy="0 0 0" xyz="0 0 0"/>
      <geometry name="relax_link2_collision">
        <mesh filename="package://relax_urdf/meshes/mesh_link2.stl" scale="0.001 0.001 0.001"/>
      </geometry>
    </collision>
  </link>
  <link name="relax_arm1_link3">
    <!-- link 3 -->
    <inertial>
      <origin xyz="0.0020858498 -0.078452653 -0.10797347"/>
      <mass value="5.9482803"/>
      <inertia ixx="0.062877846" ixy="0.00011665783" ixz="0.00012931181" iyy="0.018390664" iyz="-0.011034081" izz="0.055056825999999996"/>
    </inertial>
    <visual>
      <origin rpy="0 0 0" xyz="0 0 0"/>
      <geometry name="relax_link3_visual">
        <mesh filename="package://relax_urdf/meshes/mesh_link3.stl" scale="0.001 0.001 0.001"/>
      </geometry>
      <material name="darkblue"/>
    </visual>
    <collision>
      <origin rpy="0 0 0" xyz="0 0 0"/>
      <geometry name="relax_link3_collision">
        <mesh filename="package://relax_urdf/meshes/mesh_link3.stl" scale="0.001 0.001 0.001"/>
      </geometry>
    </collision>
  </link>
  <link name="relax_arm1_link4">
    <!-- link 4 -->
    <inertial>
      <origin xyz="0.00096471566 -0.0042586853 0.046169896"/>
      <mass value="1.6710337"/>
      <inertia ixx="0.017329393999999998" ixy="0.00021094011" ixz="-0.00024511391" iyy="0.010036060999999999" iyz="0.00042230531" izz="0.012350325"/>
    </inertial>
    <visual>
      <origin rpy="0 0 0" xyz="0 0 0"/>
      <geometry name="relax_link4_visual">
        <mesh filename="package://relax_urdf/meshes/mesh_link4.stl" scale="0.001 0.001 0.001"/>
      </geometry>
      <material name="darkblue"/>
    </visual>
    <collision>
      <origin rpy="0 0 0" xyz="0 0 0"/>
      <geometry name="relax_link4_collision">
        <mesh filename="package://relax_urdf/meshes/mesh_link4.stl" scale="0.001 0.001 0.001"/>
      </geometry>
    </collision>
  </link>
  <link name="relax_arm1_link5">
    <!-- link 5 -->
    <inertial>
      <origin xyz="-0.0013991722 0.052618238 -0.08425954199999999"/>
      <mass value="6.181102"/>
      <inertia ixx="0.059736008" ixy="-0.00014975682" ixz="-5.2815066e-05" iyy="0.015244194999999999" iyz="0.0011994937999999999" izz="0.055701504"/>
    </inertial>
    <visual>
      <origin rpy="0 0 0" xyz="0 0 0"/>
      <geometry name="relax_link5_visual">
        <mesh filename="package://relax_urdf/meshes/mesh_link5.stl" scale="0.001 0.001 0.001"/>
      </geometry>
      <material name="darkblue"/>
    </visual>
    <collision>
      <origin rpy="0 0 0" xyz="0 0 0"/>
      <geometry name="relax_link5_collision">
        <mesh filename="package://relax_urdf/meshes/mesh_link5.stl" scale="0.001 0.001 0.001"/>
      </geometry>
    </collision>
  </link>
  <link name="relax_arm1_link6">
    <!-- link 6 -->
    <inertial>
      <origin xyz="0.0005687903199999999 0.0 0.0022653642000000002"/>
      <mass value="0.48141935"/>
      <inertia ixx="0.0008220642" ixy="1.0675057e-07" ixz="3.5319177e-07" iyy="0.00083596992" iyz="0.0" izz="0.0012890535"/>
    </inertial>
    <visual>
      <origin rpy="0 0 0" xyz="0 0 0"/>
      <geometry name="relax_link6_visual">
        <mesh filename="package://relax_urdf/meshes/mesh_link6.stl" scale="0.001 0.001 0.001"/>
      </geometry>
      <material name="darkblue"/>
    </visual>
    <collision>
      <origin rpy="0 0 0" xyz="0 0 0"/>
      <geometry name="relax_link6_collision">
        <mesh filename="package://relax_urdf/meshes/mesh_link6.stl" scale="0.001 0.001 0.001"/>
      </geometry>
    </collision>
  </link>
  <link name="relax_arm1_linkEndEffector"/>
  <!-- link End-Effector -->
  <!-- joints -->
  <joint name="relax_arm1_joint0" type="revolute">
    <!-- joint 1 -->
    <parent link="base_link"/>
    <child link="relax_arm1_link1"/>
    <origin rpy="0.0 0.0 0.0" xyz="-0.13 0.0 0.3613"/>
    <axis xyz="0 0 1"/>
    <limit effort="147.0" lower="-2.7" upper="2.7" velocity="3.86"/>
    <dynamics damping="0.2" friction="10.0"/>
  </joint>
  <joint name="relax_arm1_joint1" type="revolute">
    <!-- joint 1 -->
    <parent link="relax_arm1_link1"/>
    <child link="relax_arm1_link2"/>
    <origin rpy="-1.5707963 0.0 0.0" xyz="0.0 0.13166 0.24966"/>
    <axis xyz="0 0 1"/>
    <limit effort="147.0" lower="-2.7" upper="2.7" velocity="3.86"/>
    <dynamics damping="0.2" friction="10.0"/>
  </joint>
  <joint name="relax_arm1_joint2" type="revolute">
    <!-- joint 2 -->
    <parent link="relax_arm1_link2"/>
    <child link="relax_arm1_link3"/>
    <origin rpy="0.0 0.0 0.0" xyz="0.0 -0.4 0.0"/>
    <axis xyz="0 0 -1"/>
    <limit effort="147.0" lower="-2.7" upper="2.7" velocity="3.86"/>
    <dynamics damping="0.2" friction="10.0"/>
  </joint>
  <joint name="relax_arm1_joint3" type="revolute">
    <!-- joint 3 -->
    <parent link="relax_arm1_link3"/>
    <child link="relax_arm1_link4"/>
    <origin rpy="1.5707963 0.0 0.0" xyz="0.0 -0.24966 -0.13166"/>
    <axis xyz="0 0 -1"/>
    <limit effort="147.0" lower="-2.7" upper="2.7" velocity="3.86"/>
    <dynamics damping="0.2" friction="10.0"/>
  </joint>
  <joint name="relax_arm1_joint4" type="revolute">
    <!-- joint 4 -->
    <parent link="relax_arm1_link4"/>
    <child link="relax_arm1_link5"/>
    <origin rpy="1.5707963 0.0 0.0" xyz="0.0 -0.08816 0.1535"/>
    <axis xyz="0 0 -1"/>
    <limit effort="147.0" lower="-2.0" upper="2.0" velocity="3.86"/>
    <dynamics damping="0.2" friction="10.0"/>
  </joint>
  <joint name="relax_arm1_joint5" type="revolute">
    <!-- joint 5 -->
    <parent link="relax_arm1_link5"/>
    <child link="relax_arm1_link6"/>
    <origin rpy="-1.5707963 0.0 0.0" xyz="0.0 0.22216 -0.08816"/>
    <axis xyz="0 0 1"/>
    <limit effort="147.0" lower="-2.7" upper="2.7" velocity="3.86"/>
    <dynamics damping="0.2" friction="10.0"/>
  </joint>
  <joint name="relax_arm1_joint6" type="fixed">
    <!-- joint 6 fake -->
    <parent link="relax_arm1_link6"/>
    <child link="relax_arm1_linkEndEffector"/>
    <origin rpy="0.0 0.0 0.0" xyz="0.0 0.0 0.028"/>
  </joint>
  <link name="base_link">
    <inertial>
      <origin rpy="0 0 0" xyz="0 0 0"/>
      <mass value="1"/>
      <inertia ixx="1e-4" ixy="0" ixz="0" iyy="1e-4" iyz="0" izz="1e-4"/>
    </inertial>
    <visual>
      <geometry>
        <mesh filename="package://relax_urdf/meshes/mesh_base.stl" scale="0.001 0.001 0.001"/>
      </geometry>
      <material name="dark_grey"/>
    </visual>
  </link>
  <!-- end_effector attached -->
  <!-- <xacro:if value="${ADD_END_EFFECTOR}">
      <xacro:include filename="$(find relax_urdf)/urdf/parts/end_effector.urdf.xacro" />

      <xacro:end_effector arm_num="1"  parent_link="arm1_7">
                  <origin xyz="0. 0. 0." rpy="0. 0. 0."/>
      </xacro:end_effector>

      <xacro:end_effector arm_num="2"  parent_link="arm2_7">
                  <origin xyz="0. 0. 0." rpy="0. 0. 0."/>
      </xacroend_effector>
</xacro:if> -->
</robot>
