<?xml version="1.0" ?>
<robot name="relax" version="1.0">
  <material name="darkblue">
    <color rgba="0.0 0.3 0.9 1.0"/>
  </material>
  <material name="dark">
    <color rgba="0.1 0.1 0.1 1.0"/>
  </material>
  <link name="relax_arm1_link1">
    <inertial>
      <origin xyz="-0.0018991406 0.022645162 0.16741297" rpy="0 0 0"/>
      <mass value="6.2381702"/>
      <inertia ixx="0.065816037" ixy="-0.00011791629" ixz="-4.0067927e-05" iyy="0.057828314" iyz="-0.011584403" izz="0.01940196"/>
    </inertial>
    <visual>
      <origin xyz="0.0 0.0 0.0" rpy="0.0 0.0 0.0"/>
      <geometry>
        <mesh filename="package://relax_urdf/meshes/mesh_link1.stl" scale="0.001 0.001 0.001"/>
      </geometry>
      <material name="darkblue"/>
    </visual>
    <collision>
      <origin xyz="1.27448e-05 0.0080130685 0.18331350000000002" rpy="3.026920884699987 0.0003566849008104247 0.00621413308723434"/>
      <geometry>
        <cylinder radius="0.0915579" length="0.13791276538840705"/>
      </geometry>
    </collision>
    <collision>
      <origin xyz="-0.000012 0.015903 0.251817" rpy="3.026920884699987 0.0003566849008104247 0.00621413308723434"/>
      <geometry>
        <sphere radius="0.0915579"/>
      </geometry>
    </collision>
    <collision>
      <origin xyz="0.000037 0.000123 0.114810" rpy="3.026920884699987 0.0003566849008104247 0.00621413308723434"/>
      <geometry>
        <sphere radius="0.0915579"/>
      </geometry>
    </collision>
  </link>
  <link name="relax_arm1_link2">
    <inertial>
      <origin xyz="-3.1494342e-05 -0.20005579 -0.0057041875" rpy="0 0 0"/>
      <mass value="2.601371"/>
      <inertia ixx="0.064570453" ixy="-0.00019926537999999998" ixz="-1.6866045999999998e-06" iyy="0.0051512542" iyz="-2.9627309e-06" izz="0.06672465300000001"/>
    </inertial>
    <visual>
      <origin xyz="0.0 0.0 0.0" rpy="0.0 0.0 0.0"/>
      <geometry>
        <mesh filename="package://relax_urdf/meshes/mesh_link2.stl" scale="0.001 0.001 0.001"/>
      </geometry>
      <material name="dark"/>
    </visual>
    <collision>
      <origin xyz="6.627765e-09 -0.2000087888 -0.0145835" rpy="-1.570798825542884 -7.62859514660638e-08 7.628614208566964e-08"/>
      <geometry>
        <cylinder radius="0.0779127" length="0.4002004224012504"/>
      </geometry>
    </collision>
    <collision>
      <origin xyz="0.000000 -0.400109 -0.014583" rpy="-1.570798825542884 -7.62859514660638e-08 7.628614208566964e-08"/>
      <geometry>
        <sphere radius="0.0779127"/>
      </geometry>
    </collision>
    <collision>
      <origin xyz="-0.000000 0.000091 -0.014584" rpy="-1.570798825542884 -7.62859514660638e-08 7.628614208566964e-08"/>
      <geometry>
        <sphere radius="0.0779127"/>
      </geometry>
    </collision>
  </link>
  <link name="relax_arm1_link3">
    <inertial>
      <origin xyz="0.0020858498 -0.078452653 -0.10797347" rpy="0 0 0"/>
      <mass value="5.9482803"/>
      <inertia ixx="0.062877846" ixy="0.00011665783" ixz="0.00012931181" iyy="0.018390664" iyz="-0.011034081" izz="0.055056825999999996"/>
    </inertial>
    <visual>
      <origin xyz="0.0 0.0 0.0" rpy="0.0 0.0 0.0"/>
      <geometry>
        <mesh filename="package://relax_urdf/meshes/mesh_link3.stl" scale="0.001 0.001 0.001"/>
      </geometry>
      <material name="darkblue"/>
    </visual>
    <collision>
      <origin xyz="2.628750000000001e-06 -0.06550102000000001 -0.1240435" rpy="-1.4622056613977197 0.00023368259885343988 -0.00020959122120104543"/>
      <geometry>
        <cylinder radius="0.0921787" length="0.1380269667138794"/>
      </geometry>
    </collision>
    <collision>
      <origin xyz="-0.000013 -0.134108 -0.131523" rpy="-1.4622056613977197 0.00023368259885343988 -0.00020959122120104543"/>
      <geometry>
        <sphere radius="0.0921787"/>
      </geometry>
    </collision>
    <collision>
      <origin xyz="0.000019 0.003106 -0.116564" rpy="-1.4622056613977197 0.00023368259885343988 -0.00020959122120104543"/>
      <geometry>
        <sphere radius="0.0921787"/>
      </geometry>
    </collision>
  </link>
  <link name="relax_arm1_link4">
    <inertial>
      <origin xyz="0.00096471566 -0.0042586853 0.046169896" rpy="0 0 0"/>
      <mass value="1.6710337"/>
      <inertia ixx="0.017329393999999998" ixy="0.00021094011" ixz="-0.00024511391" iyy="0.010036060999999999" iyz="0.00042230531" izz="0.012350325"/>
    </inertial>
    <visual>
      <origin xyz="0.0 0.0 0.0" rpy="0.0 0.0 0.0"/>
      <geometry>
        <mesh filename="package://relax_urdf/meshes/mesh_link4.stl" scale="0.001 0.001 0.001"/>
      </geometry>
      <material name="darkblue"/>
    </visual>
    <collision>
      <origin xyz="3.900474999999999e-06 2.995635e-06 0.08748095" rpy="-6.579347097687788e-05 0.00011540250586511395 -3.796365715055323e-09"/>
      <geometry>
        <cylinder radius="0.115074" length="0.1319941011646182"/>
      </geometry>
    </collision>
    <collision>
      <origin xyz="-0.000004 -0.000001 0.021484" rpy="-6.579347097687788e-05 0.00011540250586511395 -3.796365715055323e-09"/>
      <geometry>
        <sphere radius="0.115074"/>
      </geometry>
    </collision>
    <collision>
      <origin xyz="0.000012 0.000007 0.153478" rpy="-6.579347097687788e-05 0.00011540250586511395 -3.796365715055323e-09"/>
      <geometry>
        <sphere radius="0.115074"/>
      </geometry>
    </collision>
  </link>
  <link name="relax_arm1_link5">
    <inertial>
      <origin xyz="-0.0013991722 0.052618238 -0.08425954199999999" rpy="0 0 0"/>
      <mass value="6.181102"/>
      <inertia ixx="0.059736008" ixy="-0.00014975682" ixz="-5.2815066e-05" iyy="0.015244194999999999" iyz="0.0011994937999999999" izz="0.055701504"/>
    </inertial>
    <visual>
      <origin xyz="0.0 0.0 0.0" rpy="0.0 0.0 0.0"/>
      <geometry>
        <mesh filename="package://relax_urdf/meshes/mesh_link5.stl" scale="0.001 0.001 0.001"/>
      </geometry>
      <material name="darkblue"/>
    </visual>
    <collision>
      <origin xyz="4.59689e-05 0.023164550000000002 -0.08812225" rpy="-1.569142743279265 0.001909333046753714 -0.0019061784145204248"/>
      <geometry>
        <cylinder radius="0.104678" length="0.13080711726714422"/>
      </geometry>
    </collision>
    <collision>
      <origin xyz="-0.000079 -0.042239 -0.088230" rpy="-1.569142743279265 0.001909333046753714 -0.0019061784145204248"/>
      <geometry>
        <sphere radius="0.104678"/>
      </geometry>
    </collision>
    <collision>
      <origin xyz="0.000171 0.088568 -0.088014" rpy="-1.569142743279265 0.001909333046753714 -0.0019061784145204248"/>
      <geometry>
        <sphere radius="0.104678"/>
      </geometry>
    </collision>
  </link>
  <link name="relax_arm1_link6">
    <inertial>
      <origin xyz="0.0005687903199999999 0.0 0.0022653642000000002" rpy="0 0 0"/>
      <mass value="0.48141935"/>
      <inertia ixx="0.0008220642" ixy="1.0675057e-07" ixz="3.5319177e-07" iyy="0.00083596992" iyz="0.0" izz="0.0012890535"/>
    </inertial>
    <visual>
      <origin xyz="0.0 0.0 0.0" rpy="0.0 0.0 0.0"/>
      <geometry>
        <mesh filename="package://relax_urdf/meshes/mesh_link6.stl" scale="0.001 0.001 0.001"/>
      </geometry>
      <material name="darkblue"/>
    </visual>
    <collision>
      <origin xyz="2.333865e-07 -5.2943999999999994e-09 -0.02024995" rpy="0.0 1.5707963267948966 -0.0"/>
      <geometry>
        <cylinder radius="0.0752452" length="5.659878616105297e-07"/>
      </geometry>
    </collision>
    <collision>
      <origin xyz="-0.000000 -0.000000 -0.020250" rpy="0.0 1.5707963267948966 -0.0"/>
      <geometry>
        <sphere radius="0.0752452"/>
      </geometry>
    </collision>
    <collision>
      <origin xyz="0.000001 -0.000000 -0.020250" rpy="0.0 1.5707963267948966 -0.0"/>
      <geometry>
        <sphere radius="0.0752452"/>
      </geometry>
    </collision>
  </link>
  <link name="relax_arm1_linkEndEffector"/>
  <joint name="relax_arm1_joint0" type="revolute">
    <origin xyz="-0.13 0.0 0.3613" rpy="0.0 0.0 0.0"/>
    <axis xyz="0.0 0.0 1.0"/>
    <parent link="base_link"/>
    <child link="relax_arm1_link1"/>
    <limit effort="147.0" lower="-3.14" upper="3.14" velocity="3.86"/>
    <dynamics damping="0.2" friction="10.0"/>
  </joint>
  <joint name="relax_arm1_joint1" type="revolute">
    <origin xyz="0.0 0.13166 0.24966" rpy="-1.5707963 0.0 0.0"/>
    <axis xyz="0.0 0.0 1.0"/>
    <parent link="relax_arm1_link1"/>
    <child link="relax_arm1_link2"/>
    <limit effort="147.0" lower="-3.14" upper="3.14" velocity="3.86"/>
    <dynamics damping="0.2" friction="10.0"/>
  </joint>
  <joint name="relax_arm1_joint2" type="revolute">
    <origin xyz="0.0 -0.4 0.0" rpy="0.0 0.0 0.0"/>
    <axis xyz="0.0 0.0 1.0"/>
    <parent link="relax_arm1_link2"/>
    <child link="relax_arm1_link3"/>
    <limit effort="147.0" lower="-3.14" upper="3.14" velocity="3.86"/>
    <dynamics damping="0.2" friction="10.0"/>
  </joint>
  <joint name="relax_arm1_joint3" type="revolute">
    <origin xyz="0.0 -0.24966 -0.13166" rpy="1.5707963 0.0 0.0"/>
    <axis xyz="0.0 0.0 1.0"/>
    <parent link="relax_arm1_link3"/>
    <child link="relax_arm1_link4"/>
    <limit effort="147.0" lower="-3.14" upper="3.14" velocity="3.86"/>
    <dynamics damping="0.2" friction="10.0"/>
  </joint>
  <joint name="relax_arm1_joint4" type="revolute">
    <origin xyz="0.0 -0.08816 0.1535" rpy="1.5707963 0.0 0.0"/>
    <axis xyz="0.0 0.0 1.0"/>
    <parent link="relax_arm1_link4"/>
    <child link="relax_arm1_link5"/>
    <limit effort="147.0" lower="-3.14" upper="3.14" velocity="3.86"/>
    <dynamics damping="0.2" friction="10.0"/>
  </joint>
  <joint name="relax_arm1_joint5" type="revolute">
    <origin xyz="0.0 0.22216 -0.08816" rpy="-1.5707963 0.0 0.0"/>
    <axis xyz="0.0 0.0 1.0"/>
    <parent link="relax_arm1_link5"/>
    <child link="relax_arm1_link6"/>
    <limit effort="147.0" lower="-3.14" upper="3.14" velocity="3.86"/>
    <dynamics damping="0.2" friction="10.0"/>
  </joint>
  <joint name="relax_arm1_joint6" type="fixed">
    <origin xyz="0.0 0.0 0.028" rpy="0.0 0.0 0.0"/>
    <axis xyz="0.0 0.0 1.0"/>
    <parent link="relax_arm1_link6"/>
    <child link="relax_arm1_linkEndEffector"/>
    <limit effort="147.0" lower="-3.14" upper="3.14" velocity="3.86"/>
    <dynamics damping="0.2" friction="10.0"/>
  </joint>
  <link name="base_footprint"/>
  <joint name="base_joint" type="fixed">
    <origin xyz="0.0 0.0 0.0" rpy="0.0 0.0 0.0"/>
    <parent link="base_footprint"/>
    <child link="base_link"/>
  </joint>
  <link name="base_link">
    <inertial>
      <origin xyz="-0.054485000000000006 0.0 0.15" rpy="0.0 0.0 0.0"/>
      <mass value="97.0"/>
      <inertia ixx="1.050832913" ixy="0.0" ixz="0.0" iyy="2.344165729" iyz="0.0" izz="2.7483322339999994"/>
    </inertial>
    <visual>
      <origin xyz="-0.004485 0.0 0.0" rpy="0.0 0.0 0.0"/>
      <geometry>
        <mesh filename="package://relax_urdf/meshes/mesh_base_revised.stl" scale="0.001 0.001 0.001"/>
      </geometry>
      <material name="dark_grey">
        <color rgba="0.3 0.3 0.3 1.0"/>
      </material>
    </visual>
    <collision>
      <origin xyz="0.0 5.9102329999999995e-08 0.218567" rpy="-1.5707963265650648 1.5707960603723925 -1.5707960601425608"/>
      <geometry>
        <cylinder radius="0.319357" length="0.4739740000000168"/>
      </geometry>
    </collision>
    <collision>
      <origin xyz="-0.236987 -0.000000 0.218567" rpy="-1.5707963265650648 1.5707960603723925 -1.5707960601425608"/>
      <geometry>
        <sphere radius="0.319357"/>
      </geometry>
    </collision>
    <collision>
      <origin xyz="0.236987 0.000000 0.218567" rpy="-1.5707963265650648 1.5707960603723925 -1.5707960601425608"/>
      <geometry>
        <sphere radius="0.319357"/>
      </geometry>
    </collision>
  </link>
  <gazebo reference="base_link">
    <material>Gazebo/DarkGrey</material>
  </gazebo>
  <joint name="base_link_to_imu_joint" type="fixed">
    <origin xyz="0.0 0.0 0.25" rpy="0.0 0.0 0.0"/>
    <parent link="base_link"/>
    <child link="imu_link"/>
  </joint>
  <link name="imu_link"/>
  <gazebo>
    <plugin filename="libhector_gazebo_ros_imu.so" name="imu_plugin">
      <updateRate>50.0</updateRate>
      <bodyName>imu_link</bodyName>
      <frameId>imu_frame</frameId>
      <topicName>imu_data</topicName>
      <accelDrift>0.0 0.0 0.0</accelDrift>
      <accelGaussianNoise>0.007071067811865475 0.01 0.011401754250991379</accelGaussianNoise>
      <rateDrift>0.0 0.0 0.0</rateDrift>
      <rateGaussianNoise>0.00282842712474619 0.00282842712474619 0.0005477225575051661</rateGaussianNoise>
      <yawDrift>0.0</yawDrift>
      <yawGaussianNoise>0.31622776601683794</yawGaussianNoise>
    </plugin>
  </gazebo>
  <joint name="imu_link_to_imu_frame_joint" type="fixed">
    <origin xyz="0.0 0.0 0.0" rpy="0.0 0.0 0.0"/>
    <parent link="imu_link"/>
    <child link="imu_frame"/>
  </joint>
  <link name="imu_frame"/>
  <joint name="base_link_to_front_laser_joint" type="fixed">
    <origin xyz="0.310515 0.205 0.1914" rpy="0.0 0.0 0.7853981633974483"/>
    <parent link="base_link"/>
    <child link="front_laser_link"/>
  </joint>
  <link name="front_laser_link">
    <inertial>
      <origin xyz="0.0 0.0 0.0" rpy="0 0 0"/>
      <mass value="1.2"/>
      <inertia ixx="0.005824997669999999" ixy="0.0" ixz="0.0" iyy="0.00585609765756" iyz="0.0" izz="0.00483609806556"/>
    </inertial>
    <visual>
      <origin xyz="0.0 0.0 0.0" rpy="3.141592653589793 0.0 0.0"/>
      <geometry>
        <mesh filename="package://relax_urdf/meshes/sick_lms-100.stl"/>
      </geometry>
      <material name="black">
        <color rgba="0.1 0.1 0.1 1.0"/>
      </material>
    </visual>
    <collision>
      <origin xyz="-0.01062221 0.000515785915 -0.052592099999999996" rpy="0.012995661989790552 0.10325890353374433 0.0006715651359949701"/>
      <geometry>
        <cylinder radius="0.0694408" length="0.08046897400091513"/>
      </geometry>
    </collision>
    <collision>
      <origin xyz="-0.014769 0.001036 -0.092609" rpy="0.012995661989790552 0.10325890353374433 0.0006715651359949701"/>
      <geometry>
        <sphere radius="0.0694408"/>
      </geometry>
    </collision>
    <collision>
      <origin xyz="-0.006475 -0.000004 -0.012575" rpy="0.012995661989790552 0.10325890353374433 0.0006715651359949701"/>
      <geometry>
        <sphere radius="0.0694408"/>
      </geometry>
    </collision>
  </link>
  <gazebo reference="front_laser_link">
    <material value="Gazebo/FlatBlack"/>
    <sensor name="front_laser_link" type="ray">
      <pose>0 0 0 0 0 0</pose>
      <visualize>false</visualize>
      <update_rate>12.5</update_rate>
      <ray>
        <scan>
          <horizontal>
            <samples>541</samples>
            <resolution>1</resolution>
            <min_angle>-2.35619449615</min_angle>
            <max_angle>2.35619449615</max_angle>
          </horizontal>
        </scan>
        <range>
          <min>0.05</min>
          <max>29.0</max>
          <resolution>0.01</resolution>
        </range>
        <noise>
          <type>gaussian</type>
          <mean>0.0</mean>
          <stddev>0.01</stddev>
        </noise>
      </ray>
      <plugin filename="libgazebo_ros_laser.so" name="gazebo_ros_front_laser_link_controller">
        <frameName>front_laser_link</frameName>
        <topicName>f_scan</topicName>
      </plugin>
    </sensor>
  </gazebo>
  <joint name="base_link_to_back_laser_joint" type="fixed">
    <origin xyz="-0.319485 -0.205 0.1914" rpy="0.0 0.0 -2.356194490192345"/>
    <parent link="base_link"/>
    <child link="back_laser_link"/>
  </joint>
  <link name="back_laser_link">
    <inertial>
      <origin xyz="0.0 0.0 0.0" rpy="0 0 0"/>
      <mass value="1.2"/>
      <inertia ixx="0.005824997669999999" ixy="0.0" ixz="0.0" iyy="0.00585609765756" iyz="0.0" izz="0.00483609806556"/>
    </inertial>
    <visual>
      <origin xyz="0.0 0.0 0.0" rpy="3.141592653589793 0.0 0.0"/>
      <geometry>
        <mesh filename="package://relax_urdf/meshes/sick_lms-100.stl"/>
      </geometry>
      <material name="black">
        <color rgba="0.1 0.1 0.1 1.0"/>
      </material>
    </visual>
    <collision>
      <origin xyz="-0.01062221 -0.0005157859149999936 0.052592099999999996" rpy="-3.128596991600003 -0.10325890353374433 -0.0006715651359949574"/>
      <geometry>
        <cylinder radius="0.0694408" length="0.08046897400091513"/>
      </geometry>
    </collision>
    <collision>
      <origin xyz="-0.014769 -0.001036 0.092609" rpy="-3.128596991600003 -0.10325890353374433 -0.0006715651359949574"/>
      <geometry>
        <sphere radius="0.0694408"/>
      </geometry>
    </collision>
    <collision>
      <origin xyz="-0.006475 0.000004 0.012575" rpy="-3.128596991600003 -0.10325890353374433 -0.0006715651359949574"/>
      <geometry>
        <sphere radius="0.0694408"/>
      </geometry>
    </collision>
  </link>
  <gazebo reference="back_laser_link">
    <material value="Gazebo/FlatBlack"/>
    <sensor name="back_laser_link" type="ray">
      <pose>0 0 0 0 0 0</pose>
      <visualize>false</visualize>
      <update_rate>12.5</update_rate>
      <ray>
        <scan>
          <horizontal>
            <samples>541</samples>
            <resolution>1</resolution>
            <min_angle>-2.35619449615</min_angle>
            <max_angle>2.35619449615</max_angle>
          </horizontal>
        </scan>
        <range>
          <min>0.05</min>
          <max>29.0</max>
          <resolution>0.01</resolution>
        </range>
        <noise>
          <type>gaussian</type>
          <mean>0.0</mean>
          <stddev>0.01</stddev>
        </noise>
      </ray>
      <plugin filename="libgazebo_ros_laser.so" name="gazebo_ros_back_laser_link_controller">
        <frameName>back_laser_link</frameName>
        <topicName>b_scan</topicName>
      </plugin>
    </sensor>
  </gazebo>
  <joint name="us_1_joint" type="fixed">
    <origin xyz="0.45 -0.12 0.16" rpy="0.0 0.0 0.0"/>
    <parent link="base_link"/>
    <child link="us_1_frame"/>
  </joint>
  <link name="us_1_frame"/>
  <joint name="us_2_joint" type="fixed">
    <origin xyz="0.45 0.12 0.16" rpy="0.0 0.0 0.0"/>
    <parent link="base_link"/>
    <child link="us_2_frame"/>
  </joint>
  <link name="us_2_frame"/>
  <joint name="left_wheel_joint" type="continuous">
    <origin xyz="0.0 0.2015 0.1" rpy="0.0 0.0 0.0"/>
    <axis xyz="0.0 1.0 0.0"/>
    <parent link="base_link"/>
    <child link="left_wheel_link"/>
    <limit effort="100.0" lower="0" upper="0" velocity="20.0"/>
  </joint>
  <link name="left_wheel_link">
    <inertial>
      <origin xyz="0.0 0.0 0.0" rpy="0.0 0.0 0.0"/>
      <mass value="1.0"/>
      <inertia ixx="0.0026203322852000007" ixy="0.0" ixz="0.0" iyy="0.0026203322852000007" iyz="0.0" izz="0.005000000000000001"/>
    </inertial>
    <visual>
      <origin xyz="0.0 0.0 0.0" rpy="1.5707963267948966 0.0 0.0"/>
      <geometry>
        <cylinder radius="0.1" length="0.038"/>
      </geometry>
      <material name="black">
        <color rgba="0.1 0.1 0.1 1.0"/>
      </material>
    </visual>
    <collision>
      <origin xyz="0.0 0.0 0.0" rpy="1.5707963267948966 0.0 0.0"/>
      <geometry>
        <cylinder radius="0.1" length="0.038"/>
      </geometry>
    </collision>
    <collision>
      <origin xyz="0.000000 0.019000 -0.000000" rpy="1.5707963267948966 0.0 0.0"/>
      <geometry>
        <sphere radius="0.1"/>
      </geometry>
    </collision>
    <collision>
      <origin xyz="0.000000 -0.019000 0.000000" rpy="1.5707963267948966 0.0 0.0"/>
      <geometry>
        <sphere radius="0.1"/>
      </geometry>
    </collision>
  </link>
  <gazebo reference="left_wheel_link">
    <material>Gazebo/FlatBlack</material>
  </gazebo>
  <joint name="right_wheel_joint" type="continuous">
    <origin xyz="0.0 -0.2015 0.1" rpy="0.0 0.0 0.0"/>
    <axis xyz="0.0 1.0 0.0"/>
    <parent link="base_link"/>
    <child link="right_wheel_link"/>
    <limit effort="100.0" lower="0" upper="0" velocity="20.0"/>
  </joint>
  <link name="right_wheel_link">
    <inertial>
      <origin xyz="0.0 0.0 0.0" rpy="0.0 0.0 0.0"/>
      <mass value="1.0"/>
      <inertia ixx="0.0026203322852000007" ixy="0.0" ixz="0.0" iyy="0.0026203322852000007" iyz="0.0" izz="0.005000000000000001"/>
    </inertial>
    <visual>
      <origin xyz="0.0 0.0 0.0" rpy="1.5707963267948966 0.0 0.0"/>
      <geometry>
        <cylinder radius="0.1" length="0.038"/>
      </geometry>
      <material name="black">
        <color rgba="0.1 0.1 0.1 1.0"/>
      </material>
    </visual>
    <collision>
      <origin xyz="0.0 0.0 0.0" rpy="1.5707963267948966 0.0 0.0"/>
      <geometry>
        <cylinder radius="0.1" length="0.038"/>
      </geometry>
    </collision>
    <collision>
      <origin xyz="0.000000 0.019000 -0.000000" rpy="1.5707963267948966 0.0 0.0"/>
      <geometry>
        <sphere radius="0.1"/>
      </geometry>
    </collision>
    <collision>
      <origin xyz="0.000000 -0.019000 0.000000" rpy="1.5707963267948966 0.0 0.0"/>
      <geometry>
        <sphere radius="0.1"/>
      </geometry>
    </collision>
  </link>
  <gazebo reference="right_wheel_link">
    <material>Gazebo/FlatBlack</material>
  </gazebo>
  <joint name="fl_caster_rotation_joint" type="continuous">
    <origin xyz="0.299215 0.188 0.1565" rpy="0.0 0.0 0.0"/>
    <axis xyz="0.0 0.0 1.0"/>
    <parent link="base_link"/>
    <child link="fl_caster_rotation_link"/>
    <dynamics damping="0.01" friction="0.0"/>
  </joint>
  <link name="fl_caster_rotation_link">
    <inertial>
      <origin xyz="0.0 0.0 -0.042500000044" rpy="0.0 0.0 0.0"/>
      <mass value="0.3097539019"/>
      <inertia ixx="0.0005844517978" ixy="0.0" ixz="0.0" iyy="0.00052872551237" iyz="0.0" izz="0.00017923555074"/>
    </inertial>
    <visual>
      <origin xyz="0.0 0.0 0.0" rpy="0.0 0.0 0.0"/>
      <geometry>
        <mesh filename="package://relax_urdf/meshes/caster_wheel_base.stl"/>
      </geometry>
      <material name="black">
        <color rgba="0.1 0.1 0.1 1.0"/>
      </material>
    </visual>
    <collision>
      <origin xyz="-0.013977 -0.000330265 -0.0551619" rpy="0.003020243748649022 0.39799658655106795 0.0006090850838832768"/>
      <geometry>
        <cylinder radius="0.0393866" length="0.08979176363609312"/>
      </geometry>
    </collision>
    <collision>
      <origin xyz="-0.031377 -0.000205 -0.096548" rpy="0.003020243748649022 0.39799658655106795 0.0006090850838832768"/>
      <geometry>
        <sphere radius="0.0393866"/>
      </geometry>
    </collision>
    <collision>
      <origin xyz="0.003423 -0.000455 -0.013775" rpy="0.003020243748649022 0.39799658655106795 0.0006090850838832768"/>
      <geometry>
        <sphere radius="0.0393866"/>
      </geometry>
    </collision>
  </link>
  <gazebo reference="fl_caster_rotation_link">
    <material>Gazebo/FlatBlack</material>
  </gazebo>
  <joint name="fl_caster_wheel_joint" type="continuous">
    <origin xyz="-0.0382 0.0 -0.094" rpy="0.0 0.0 0.0"/>
    <axis xyz="0.0 1.0 0.0"/>
    <parent link="fl_caster_rotation_link"/>
    <child link="fl_caster_wheel_link"/>
  </joint>
  <link name="fl_caster_wheel_link">
    <inertial>
      <origin xyz="0.0 0.0 0.0" rpy="0.0 0.0 0.0"/>
      <mass value="1.0"/>
      <inertia ixx="0.001061895408575" ixy="0.0" ixz="0.0" iyy="0.001061895408575" iyz="0.0" izz="0.001953125"/>
    </inertial>
    <visual>
      <origin xyz="0.0 0.0 0.0" rpy="1.5707963267948966 0.0 0.0"/>
      <geometry>
        <cylinder radius="0.0625" length="0.032"/>
      </geometry>
      <material name="black">
        <color rgba="0.1 0.1 0.1 1.0"/>
      </material>
    </visual>
    <collision>
      <origin xyz="0.0 0.0 0.0" rpy="1.5707963267948966 0.0 0.0"/>
      <geometry>
        <cylinder radius="0.0625" length="0.032"/>
      </geometry>
    </collision>
    <collision>
      <origin xyz="0.000000 0.016000 -0.000000" rpy="1.5707963267948966 0.0 0.0"/>
      <geometry>
        <sphere radius="0.0625"/>
      </geometry>
    </collision>
    <collision>
      <origin xyz="0.000000 -0.016000 0.000000" rpy="1.5707963267948966 0.0 0.0"/>
      <geometry>
        <sphere radius="0.0625"/>
      </geometry>
    </collision>
  </link>
  <gazebo reference="fl_caster_wheel_link">
    <material>Gazebo/FlatBlack</material>
  </gazebo>
  <joint name="fr_caster_rotation_joint" type="continuous">
    <origin xyz="0.299215 -0.188 0.1565" rpy="0.0 0.0 0.0"/>
    <axis xyz="0.0 0.0 1.0"/>
    <parent link="base_link"/>
    <child link="fr_caster_rotation_link"/>
    <dynamics damping="0.01" friction="0.0"/>
  </joint>
  <link name="fr_caster_rotation_link">
    <inertial>
      <origin xyz="0.0 0.0 -0.042500000044" rpy="0.0 0.0 0.0"/>
      <mass value="0.3097539019"/>
      <inertia ixx="0.0005844517978" ixy="0.0" ixz="0.0" iyy="0.00052872551237" iyz="0.0" izz="0.00017923555074"/>
    </inertial>
    <visual>
      <origin xyz="0.0 0.0 0.0" rpy="0.0 0.0 0.0"/>
      <geometry>
        <mesh filename="package://relax_urdf/meshes/caster_wheel_base.stl"/>
      </geometry>
      <material name="black">
        <color rgba="0.1 0.1 0.1 1.0"/>
      </material>
    </visual>
    <collision>
      <origin xyz="-0.013977 -0.000330265 -0.0551619" rpy="0.003020243748649022 0.39799658655106795 0.0006090850838832768"/>
      <geometry>
        <cylinder radius="0.0393866" length="0.08979176363609312"/>
      </geometry>
    </collision>
    <collision>
      <origin xyz="-0.031377 -0.000205 -0.096548" rpy="0.003020243748649022 0.39799658655106795 0.0006090850838832768"/>
      <geometry>
        <sphere radius="0.0393866"/>
      </geometry>
    </collision>
    <collision>
      <origin xyz="0.003423 -0.000455 -0.013775" rpy="0.003020243748649022 0.39799658655106795 0.0006090850838832768"/>
      <geometry>
        <sphere radius="0.0393866"/>
      </geometry>
    </collision>
  </link>
  <gazebo reference="fr_caster_rotation_link">
    <material>Gazebo/FlatBlack</material>
  </gazebo>
  <joint name="fr_caster_wheel_joint" type="continuous">
    <origin xyz="-0.0382 0.0 -0.094" rpy="0.0 0.0 0.0"/>
    <axis xyz="0.0 1.0 0.0"/>
    <parent link="fr_caster_rotation_link"/>
    <child link="fr_caster_wheel_link"/>
  </joint>
  <link name="fr_caster_wheel_link">
    <inertial>
      <origin xyz="0.0 0.0 0.0" rpy="0.0 0.0 0.0"/>
      <mass value="1.0"/>
      <inertia ixx="0.001061895408575" ixy="0.0" ixz="0.0" iyy="0.001061895408575" iyz="0.0" izz="0.001953125"/>
    </inertial>
    <visual>
      <origin xyz="0.0 0.0 0.0" rpy="1.5707963267948966 0.0 0.0"/>
      <geometry>
        <cylinder radius="0.0625" length="0.032"/>
      </geometry>
      <material name="black">
        <color rgba="0.1 0.1 0.1 1.0"/>
      </material>
    </visual>
    <collision>
      <origin xyz="0.0 0.0 0.0" rpy="1.5707963267948966 0.0 0.0"/>
      <geometry>
        <cylinder radius="0.0625" length="0.032"/>
      </geometry>
    </collision>
    <collision>
      <origin xyz="0.000000 0.016000 -0.000000" rpy="1.5707963267948966 0.0 0.0"/>
      <geometry>
        <sphere radius="0.0625"/>
      </geometry>
    </collision>
    <collision>
      <origin xyz="0.000000 -0.016000 0.000000" rpy="1.5707963267948966 0.0 0.0"/>
      <geometry>
        <sphere radius="0.0625"/>
      </geometry>
    </collision>
  </link>
  <gazebo reference="fr_caster_wheel_link">
    <material>Gazebo/FlatBlack</material>
  </gazebo>
  <joint name="bl_caster_rotation_joint" type="continuous">
    <origin xyz="-0.300485 0.188 0.1565" rpy="0.0 0.0 0.0"/>
    <axis xyz="0.0 0.0 1.0"/>
    <parent link="base_link"/>
    <child link="bl_caster_rotation_link"/>
    <dynamics damping="0.01" friction="0.0"/>
  </joint>
  <link name="bl_caster_rotation_link">
    <inertial>
      <origin xyz="0.0 0.0 -0.042500000044" rpy="0.0 0.0 0.0"/>
      <mass value="0.3097539019"/>
      <inertia ixx="0.0005844517978" ixy="0.0" ixz="0.0" iyy="0.00052872551237" iyz="0.0" izz="0.00017923555074"/>
    </inertial>
    <visual>
      <origin xyz="0.0 0.0 0.0" rpy="0.0 0.0 0.0"/>
      <geometry>
        <mesh filename="package://relax_urdf/meshes/caster_wheel_base.stl"/>
      </geometry>
      <material name="black">
        <color rgba="0.1 0.1 0.1 1.0"/>
      </material>
    </visual>
    <collision>
      <origin xyz="-0.013977 -0.000330265 -0.0551619" rpy="0.003020243748649022 0.39799658655106795 0.0006090850838832768"/>
      <geometry>
        <cylinder radius="0.0393866" length="0.08979176363609312"/>
      </geometry>
    </collision>
    <collision>
      <origin xyz="-0.031377 -0.000205 -0.096548" rpy="0.003020243748649022 0.39799658655106795 0.0006090850838832768"/>
      <geometry>
        <sphere radius="0.0393866"/>
      </geometry>
    </collision>
    <collision>
      <origin xyz="0.003423 -0.000455 -0.013775" rpy="0.003020243748649022 0.39799658655106795 0.0006090850838832768"/>
      <geometry>
        <sphere radius="0.0393866"/>
      </geometry>
    </collision>
  </link>
  <gazebo reference="bl_caster_rotation_link">
    <material>Gazebo/FlatBlack</material>
  </gazebo>
  <joint name="bl_caster_wheel_joint" type="continuous">
    <origin xyz="-0.0382 0.0 -0.094" rpy="0.0 0.0 0.0"/>
    <axis xyz="0.0 1.0 0.0"/>
    <parent link="bl_caster_rotation_link"/>
    <child link="bl_caster_wheel_link"/>
  </joint>
  <link name="bl_caster_wheel_link">
    <inertial>
      <origin xyz="0.0 0.0 0.0" rpy="0.0 0.0 0.0"/>
      <mass value="1.0"/>
      <inertia ixx="0.001061895408575" ixy="0.0" ixz="0.0" iyy="0.001061895408575" iyz="0.0" izz="0.001953125"/>
    </inertial>
    <visual>
      <origin xyz="0.0 0.0 0.0" rpy="1.5707963267948966 0.0 0.0"/>
      <geometry>
        <cylinder radius="0.0625" length="0.032"/>
      </geometry>
      <material name="black">
        <color rgba="0.1 0.1 0.1 1.0"/>
      </material>
    </visual>
    <collision>
      <origin xyz="0.0 0.0 0.0" rpy="1.5707963267948966 0.0 0.0"/>
      <geometry>
        <cylinder radius="0.0625" length="0.032"/>
      </geometry>
    </collision>
    <collision>
      <origin xyz="0.000000 0.016000 -0.000000" rpy="1.5707963267948966 0.0 0.0"/>
      <geometry>
        <sphere radius="0.0625"/>
      </geometry>
    </collision>
    <collision>
      <origin xyz="0.000000 -0.016000 0.000000" rpy="1.5707963267948966 0.0 0.0"/>
      <geometry>
        <sphere radius="0.0625"/>
      </geometry>
    </collision>
  </link>
  <gazebo reference="bl_caster_wheel_link">
    <material>Gazebo/FlatBlack</material>
  </gazebo>
  <joint name="br_caster_rotation_joint" type="continuous">
    <origin xyz="-0.300485 -0.188 0.1565" rpy="0.0 0.0 0.0"/>
    <axis xyz="0.0 0.0 1.0"/>
    <parent link="base_link"/>
    <child link="br_caster_rotation_link"/>
    <dynamics damping="0.01" friction="0.0"/>
  </joint>
  <link name="br_caster_rotation_link">
    <inertial>
      <origin xyz="0.0 0.0 -0.042500000044" rpy="0.0 0.0 0.0"/>
      <mass value="0.3097539019"/>
      <inertia ixx="0.0005844517978" ixy="0.0" ixz="0.0" iyy="0.00052872551237" iyz="0.0" izz="0.00017923555074"/>
    </inertial>
    <visual>
      <origin xyz="0.0 0.0 0.0" rpy="0.0 0.0 0.0"/>
      <geometry>
        <mesh filename="package://relax_urdf/meshes/caster_wheel_base.stl"/>
      </geometry>
      <material name="black">
        <color rgba="0.1 0.1 0.1 1.0"/>
      </material>
    </visual>
    <collision>
      <origin xyz="-0.013977 -0.000330265 -0.0551619" rpy="0.003020243748649022 0.39799658655106795 0.0006090850838832768"/>
      <geometry>
        <cylinder radius="0.0393866" length="0.08979176363609312"/>
      </geometry>
    </collision>
    <collision>
      <origin xyz="-0.031377 -0.000205 -0.096548" rpy="0.003020243748649022 0.39799658655106795 0.0006090850838832768"/>
      <geometry>
        <sphere radius="0.0393866"/>
      </geometry>
    </collision>
    <collision>
      <origin xyz="0.003423 -0.000455 -0.013775" rpy="0.003020243748649022 0.39799658655106795 0.0006090850838832768"/>
      <geometry>
        <sphere radius="0.0393866"/>
      </geometry>
    </collision>
  </link>
  <gazebo reference="br_caster_rotation_link">
    <material>Gazebo/FlatBlack</material>
  </gazebo>
  <joint name="br_caster_wheel_joint" type="continuous">
    <origin xyz="-0.0382 0.0 -0.094" rpy="0.0 0.0 0.0"/>
    <axis xyz="0.0 1.0 0.0"/>
    <parent link="br_caster_rotation_link"/>
    <child link="br_caster_wheel_link"/>
  </joint>
  <link name="br_caster_wheel_link">
    <inertial>
      <origin xyz="0.0 0.0 0.0" rpy="0.0 0.0 0.0"/>
      <mass value="1.0"/>
      <inertia ixx="0.001061895408575" ixy="0.0" ixz="0.0" iyy="0.001061895408575" iyz="0.0" izz="0.001953125"/>
    </inertial>
    <visual>
      <origin xyz="0.0 0.0 0.0" rpy="1.5707963267948966 0.0 0.0"/>
      <geometry>
        <cylinder radius="0.0625" length="0.032"/>
      </geometry>
      <material name="black">
        <color rgba="0.1 0.1 0.1 1.0"/>
      </material>
    </visual>
    <collision>
      <origin xyz="0.0 0.0 0.0" rpy="1.5707963267948966 0.0 0.0"/>
      <geometry>
        <cylinder radius="0.0625" length="0.032"/>
      </geometry>
    </collision>
    <collision>
      <origin xyz="0.000000 0.016000 -0.000000" rpy="1.5707963267948966 0.0 0.0"/>
      <geometry>
        <sphere radius="0.0625"/>
      </geometry>
    </collision>
    <collision>
      <origin xyz="0.000000 -0.016000 0.000000" rpy="1.5707963267948966 0.0 0.0"/>
      <geometry>
        <sphere radius="0.0625"/>
      </geometry>
    </collision>
  </link>
  <gazebo reference="br_caster_wheel_link">
    <material>Gazebo/FlatBlack</material>
  </gazebo>
  <joint name="base_link_surface_joint" type="fixed">
    <origin xyz="-0.004485 0.0 0.352" rpy="0.0 0.0 0.0"/>
    <axis xyz="0.0 0.0 1.0"/>
    <parent link="base_link"/>
    <child link="surface"/>
  </joint>
  <link name="surface"/>
  <transmission name="left_wheel_trans">
    <type>transmission_interface/SimpleTransmission</type>
    <joint name="left_wheel_joint">
      <hardwareInterface>hardware_interface/VelocityJointInterface</hardwareInterface>
    </joint>
    <actuator name="left_wheel_motor">
      <mechanicalReduction>1.0</mechanicalReduction>
    </actuator>
  </transmission>
  <transmission name="right_wheel_trans">
    <type>transmission_interface/SimpleTransmission</type>
    <joint name="right_wheel_joint">
      <hardwareInterface>hardware_interface/VelocityJointInterface</hardwareInterface>
    </joint>
    <actuator name="right_wheel_motor">
      <mechanicalReduction>1.0</mechanicalReduction>
    </actuator>
  </transmission>
  <gazebo reference="left_wheel_link">
    <mu1 value="200"/>
    <mu2 value="200"/>
    <kp value="10000000.0"/>
    <kd value="1.0"/>
    <minDepth>0.01</minDepth>
  </gazebo>
  <gazebo reference="right_wheel_link">
    <mu1 value="200"/>
    <mu2 value="200"/>
    <kp value="10000000.0"/>
    <kd value="1.0"/>
    <minDepth>0.01</minDepth>
  </gazebo>
  <gazebo reference="fl_caster_wheel_link">
    <mu1 value="1"/>
    <mu2 value="1"/>
    <kp value="10000000.0"/>
    <kd value="1.0"/>
    <minDepth>0.01</minDepth>
  </gazebo>
  <gazebo reference="fr_caster_wheel_link">
    <mu1 value="1"/>
    <mu2 value="1"/>
    <kp value="10000000.0"/>
    <kd value="1.0"/>
    <minDepth>0.01</minDepth>
  </gazebo>
  <gazebo reference="bl_caster_wheel_link">
    <mu1 value="1"/>
    <mu2 value="1"/>
    <kp value="10000000.0"/>
    <kd value="1.0"/>
    <minDepth>0.01</minDepth>
  </gazebo>
  <gazebo reference="br_caster_wheel_link">
    <mu1 value="1"/>
    <mu2 value="1"/>
    <kp value="10000000.0"/>
    <kd value="1.0"/>
    <minDepth>0.01</minDepth>
  </gazebo>
  <gazebo>
    <plugin filename="libgazebo_ros_p3d.so" name="p3d_base_controller">
      <alwaysOn>true</alwaysOn>
      <updateRate>50.0</updateRate>
      <bodyName>base_footprint</bodyName>
      <topicName>base_pose_ground_truth</topicName>
      <gaussianNoise>0.01</gaussianNoise>
      <frameName>map</frameName>
      <xyzOffsets>0 0 0</xyzOffsets>
      <rpyOffsets>0 0 0</rpyOffsets>
    </plugin>
  </gazebo>
</robot>