<?xml version="1.0" ?>
<!-- =================================================================================== -->
<!-- |    This document was autogenerated by xacro from /home/liana/catkin_ws/src/iit-relax-ros-pkg/relax_urdf/urdf/relax.urdf.xacro | -->
<!-- |    EDITING THIS FILE BY HAND IS NOT RECOMMENDED                                 | -->
<!-- =================================================================================== -->
<robot name="relax">
  <!-- ************SELECT PARTS*************-->
  <!-- *************************************-->
  <!-- color -->
  <material name="darkblue">
    <color rgba="0.0 0.3 0.9 1"/>
  </material>
  <material name="dark">
    <color rgba="0.1 0.1 0.1 1"/>
  </material>
  <!-- ARM -->
  <!-- ARM -->
  <!-- ARM -->
  <!-- ARM -->
  <link name="base_link"/>
  <joint name="base_joint" type="fixed">
    <parent link="base_link"/>
    <child link="mobile_base_link"/>
    <origin rpy="0 0 0" xyz="0 0 0"/>
  </joint>
  <!-- links -->
  <link name="relax_arm1_link1">
    <!-- link 1 -->
    <inertial>
      <origin xyz="0.0013955428 0.025982581 -0.16511476"/>
      <mass value="5.9029271"/>
      <inertia ixx="0.06218286099999999" ixy="8.1614096e-05" ixz="0.00010385066" iyy="0.055346023" iyz="0.01299992" izz="0.016821722"/>
    </inertial>
    <visual>
      <origin rpy="0 0 0" xyz="0 0 0"/>
      <geometry name="relax_link1_visual">
        <mesh filename="package://relax_urdf/meshes/mesh_link1.stl" scale="0.001 0.001 0.001"/>
      </geometry>
      <material name="darkblue"/>
    </visual>
    <collision>
      <origin rpy="0 0 0" xyz="0 0 0"/>
      <geometry name="relax_link1_collision">
        <mesh filename="package://relax_urdf/meshes/mesh_link1.stl" scale="0.001 0.001 0.001"/>
      </geometry>
    </collision>
  </link>
  <link name="relax_arm1_link2">
    <!-- link 2 -->
    <inertial>
      <origin xyz="0.0 -0.0071720374 -0.20000694"/>
      <mass value="1.9989653"/>
      <inertia ixx="0.049589547" ixy="-2.3822174e-08" ixz="0.00023476881" iyy="0.051111593" iyz="7.769848999999999e-07" izz="0.0040702978999999995"/>
    </inertial>
    <visual>
      <origin rpy="0 0 0" xyz="0 0 0"/>
      <geometry name="relax_link2_visual">
        <mesh filename="package://relax_urdf/meshes/mesh_link2.stl" scale="0.001 0.001 0.001"/>
      </geometry>
      <material name="dark"/>
    </visual>
    <collision>
      <origin rpy="0 0 0" xyz="0 0 0"/>
      <geometry name="relax_link2_collision">
        <mesh filename="package://relax_urdf/meshes/mesh_link2.stl" scale="0.001 0.001 0.001"/>
      </geometry>
    </collision>
  </link>
  <link name="relax_arm1_link3">
    <!-- link 3 -->
    <inertial>
      <origin xyz="-0.0021052916000000002 -0.10638552 -0.074903486"/>
      <mass value="5.8838845"/>
      <inertia ixx="0.061043599" ixy="-0.00015340890999999997" ixz="-0.0001783316" iyy="0.05360130999999999" iyz="-0.011090899999999999" izz="0.017380798"/>
    </inertial>
    <visual>
      <origin rpy="0 0 0" xyz="0 0 0"/>
      <geometry name="relax_link3_visual">
        <mesh filename="package://relax_urdf/meshes/mesh_link3.stl" scale="0.001 0.001 0.001"/>
      </geometry>
      <material name="darkblue"/>
    </visual>
    <collision>
      <origin rpy="0 0 0" xyz="0 0 0"/>
      <geometry name="relax_link3_collision">
        <mesh filename="package://relax_urdf/meshes/mesh_link3.stl" scale="0.001 0.001 0.001"/>
      </geometry>
    </collision>
  </link>
  <link name="relax_arm1_link4">
    <!-- link 4 -->
    <inertial>
      <origin xyz="0.00024496086 -0.0010728501 -0.049015064000000004"/>
      <mass value="1.398224"/>
      <inertia ixx="0.01466727" ixy="-2.0411011999999998e-05" ixz="-4.476957e-05" iyy="0.008659858099999999" iyz="-8.3199044e-05" izz="0.010450923"/>
    </inertial>
    <visual>
      <origin rpy="0 0 0" xyz="0 0 0"/>
      <geometry name="relax_link4_visual">
        <mesh filename="package://relax_urdf/meshes/mesh_link4.stl" scale="0.001 0.001 0.001"/>
      </geometry>
      <material name="darkblue"/>
    </visual>
    <collision>
      <origin rpy="0 0 0" xyz="0 0 0"/>
      <geometry name="relax_link4_collision">
        <mesh filename="package://relax_urdf/meshes/mesh_link4.stl" scale="0.001 0.001 0.001"/>
      </geometry>
    </collision>
  </link>
  <link name="relax_arm1_link5">
    <!-- link 5 -->
    <inertial>
      <origin xyz="-0.0013228834 -0.08468301 -0.053211105"/>
      <mass value="5.7923846"/>
      <inertia ixx="0.055109543" ixy="-0.00014003836999999997" ixz="0.00021470742999999998" iyy="0.051309424" iyz="-0.0010289246" izz="0.013804762"/>
    </inertial>
    <visual>
      <origin rpy="0 0 0" xyz="0 0 0"/>
      <geometry name="relax_link5_visual">
        <mesh filename="package://relax_urdf/meshes/mesh_link5.stl" scale="0.001 0.001 0.001"/>
      </geometry>
      <material name="darkblue"/>
    </visual>
    <collision>
      <origin rpy="0 0 0" xyz="0 0 0"/>
      <geometry name="relax_link5_collision">
        <mesh filename="package://relax_urdf/meshes/mesh_link5.stl" scale="0.001 0.001 0.001"/>
      </geometry>
    </collision>
  </link>
  <!-- joints -->
  <joint name="relax_arm1_joint1" type="revolute">
    <!-- joint 1 -->
    <parent link="relax_arm1_link1"/>
    <child link="relax_arm1_link2"/>
    <origin rpy="0 0 0" xyz="0.0 0.13166 -0.24966"/>
    <axis xyz="0 1 0"/>
    <limit effort="147.0" lower="-3.14" upper="3.14" velocity="3.86"/>
    <dynamics damping="0.2" friction="10.0"/>
  </joint>
  <joint name="relax_arm1_joint2" type="revolute">
    <!-- joint 2 -->
    <parent link="relax_arm1_link2"/>
    <child link="relax_arm1_link3"/>
    <origin rpy="0 0 0" xyz="0.0 0.0 -0.4"/>
    <axis xyz="0 1 0"/>
    <limit effort="147.0" lower="-3.14" upper="3.14" velocity="3.86"/>
    <dynamics damping="0.2" friction="10.0"/>
  </joint>
  <joint name="relax_arm1_joint3" type="revolute">
    <!-- joint 3 -->
    <parent link="relax_arm1_link3"/>
    <child link="relax_arm1_link4"/>
    <origin rpy="0 0 0" xyz="0.0 -0.13166 -0.24966"/>
    <axis xyz="0 0 1"/>
    <limit effort="147.0" lower="-3.14" upper="3.14" velocity="3.86"/>
    <dynamics damping="0.2" friction="10.0"/>
  </joint>
  <joint name="relax_arm1_joint4" type="revolute">
    <!-- joint 4 -->
    <parent link="relax_arm1_link4"/>
    <child link="relax_arm1_link5"/>
    <origin rpy="0.0 0.0 3.1415927" xyz="0.0 -0.08816 -0.1535"/>
    <axis xyz="0 1 0"/>
    <limit effort="147.0" lower="-3.14" upper="3.14" velocity="3.86"/>
    <dynamics damping="0.2" friction="10.0"/>
  </joint>
  <!-- end_effector attached -->
  <!-- <xacro:if value="${ADD_END_EFFECTOR}">
      <xacro:include filename="$(find relax_urdf)/urdf/parts/end_effector.urdf.xacro" />

      <xacro:end_effector arm_num="1"  parent_link="arm1_7">
                  <origin xyz="0. 0. 0." rpy="0. 0. 0."/>
      </xacro:end_effector>

      <xacro:end_effector arm_num="2"  parent_link="arm2_7">
                  <origin xyz="0. 0. 0." rpy="0. 0. 0."/>
      </xacroend_effector>
</xacro:if> -->
  <!-- links -->
  <link name="mobile_base_link">
    <!-- mobile base link -->
    <inertial>
      <origin rpy="0 0 0" xyz="0.0 0.0 0.0"/>
      <mass value="100.0"/>
      <inertia ixx="17" ixy="0.0" ixz="0.0" iyy="17" iyz="0.0" izz="17"/>
    </inertial>
    <visual>
      <origin rpy="0 0 0" xyz="0 0 0"/>
      <geometry name="mobile_base_link_visual">
        <mesh filename="package://relax_urdf/meshes/mir_base.stl" scale="0.001 0.001 0.001"/>
      </geometry>
      <material name="dark"/>
    </visual>
    <collision>
      <origin rpy="0 0 0" xyz="0 0 0"/>
      <geometry name="mobile_base_link_collision">
        <mesh filename="package://relax_urdf/meshes/mir_base.stl" scale="0.001 0.001 0.001"/>
      </geometry>
    </collision>
  </link>
  <link name="control_box">
    <inertial>
      <origin rpy="0 0 0" xyz="0.0 0.0 0.0"/>
      <mass value="1.0"/>
      <inertia ixx="0.17" ixy="0.0" ixz="0.0" iyy="0.17" iyz="0.0" izz="0.17"/>
    </inertial>
    <visual>
      <origin rpy="0 0 0" xyz="0 0 0"/>
      <geometry name="control_box_visual">
        <box size="0.3 0.3 0.15"/>
      </geometry>
      <material name="dark"/>
    </visual>
    <collision>
      <origin rpy="0 0 0" xyz="0 0 0"/>
      <geometry name="control_box_collision">
        <box size="0.3 0.3 0.15"/>
      </geometry>
    </collision>
  </link>
  <link name="left_wheel">
    <inertial>
      <origin rpy="0 0 0" xyz="0.0 0.0 0.0"/>
      <mass value="1.0"/>
      <inertia ixx="0.17" ixy="0.0" ixz="0.0" iyy="0.17" iyz="0.0" izz="0.17"/>
    </inertial>
    <visual>
      <origin rpy="0 0 0" xyz="0 0 0"/>
      <geometry name="left_wheel_link_visual">
        <mesh filename="package://relax_urdf/meshes/mesh_left_wheel.stl" scale="0.001 0.001 0.001"/>
      </geometry>
      <material name="dark"/>
    </visual>
    <collision>
      <origin rpy="0 0 0" xyz="0 0 0"/>
      <geometry name="left_wheel_link_collision">
        <mesh filename="package://relax_urdf/meshes/mesh_left_wheel.stl" scale="0.001 0.001 0.001"/>
      </geometry>
    </collision>
  </link>
  <link name="right_wheel">
    <inertial>
      <origin rpy="0 0 0" xyz="0.0 0.0 0.0"/>
      <mass value="1.0"/>
      <inertia ixx="0.17" ixy="0.0" ixz="0.0" iyy="0.17" iyz="0.0" izz="0.17"/>
    </inertial>
    <visual>
      <origin rpy="0 0 0" xyz="0 0 0"/>
      <geometry name="right_wheel_link_visual">
        <mesh filename="package://relax_urdf/meshes/mesh_left_wheel.stl" scale="0.001 0.001 0.001"/>
      </geometry>
      <material name="dark"/>
    </visual>
    <collision>
      <origin rpy="0 0 0" xyz="0 0 0"/>
      <geometry name="right_wheel_link_collision">
        <mesh filename="package://relax_urdf/meshes/mesh_left_wheel.stl" scale="0.001 0.001 0.001"/>
      </geometry>
    </collision>
  </link>
  <link name="left_wheel_yaw">
    <inertial>
      <origin rpy="0 0 0" xyz="0.0 0.0 0.0"/>
      <mass value="1.0"/>
      <inertia ixx="0.17" ixy="0.0" ixz="0.0" iyy="0.17" iyz="0.0" izz="0.17"/>
    </inertial>
    <visual>
      <origin rpy="0 0 0" xyz="0 0 0"/>
      <geometry name="left_wheel_yaw_link_visual">
        <box size="0.001 0.001 0.001"/>
      </geometry>
      <material name="dark"/>
    </visual>
    <collision>
      <origin rpy="0 0 0" xyz="0 0 0"/>
      <geometry name="left_wheel_yaw_link_collision">
        <box size="0.001 0.001 0.001"/>
      </geometry>
    </collision>
  </link>
  <link name="right_wheel_yaw">
    <inertial>
      <origin rpy="0 0 0" xyz="0.0 0.0 0.0"/>
      <mass value="1.0"/>
      <inertia ixx="0.17" ixy="0.0" ixz="0.0" iyy="0.17" iyz="0.0" izz="0.17"/>
    </inertial>
    <visual>
      <origin rpy="0 0 0" xyz="0 0 0"/>
      <geometry name="right_wheel_yaw_link_visual">
        <box size="0.001 0.001 0.001"/>
      </geometry>
      <material name="dark"/>
    </visual>
    <collision>
      <origin rpy="0 0 0" xyz="0 0 0"/>
      <geometry name="right_wheel_yaw_link_collision">
        <box size="0.001 0.001 0.001"/>
      </geometry>
    </collision>
  </link>
  <joint name="j_control" type="fixed">
    <parent link="mobile_base_link"/>
    <child link="control_box"/>
    <origin rpy="0 0 0" xyz="0 0 0.375"/>
    <axis xyz="0 0 1"/>
  </joint>
  <joint name="j_left_wheel_yaw" type="revolute">
    <parent link="mobile_base_link"/>
    <child link="left_wheel_yaw"/>
    <origin rpy="0 0 0" xyz="-0.00448719 0.25 0.09"/>
    <axis xyz="0 0 1"/>
    <limit effort="35" lower="-1" upper="1" velocity="20"/>
  </joint>
  <joint name="j_right_wheel_yaw" type="revolute">
    <parent link="mobile_base_link"/>
    <child link="right_wheel_yaw"/>
    <origin rpy="0 0 0" xyz="-0.00448719 -0.25 0.09"/>
    <axis xyz="0 0 1"/>
    <limit effort="35" lower="-1" upper="1" velocity="20"/>
  </joint>
  <joint name="j_left_wheel_roll" type="continuous">
    <parent link="left_wheel_yaw"/>
    <child link="left_wheel"/>
    <origin rpy="0 0 0" xyz="0 0 0"/>
    <axis xyz="0 1 0"/>
    <limit effort="35" velocity="20"/>
  </joint>
  <joint name="j_right_wheel_roll" type="continuous">
    <parent link="right_wheel_yaw"/>
    <child link="right_wheel"/>
    <origin rpy="0 0 0" xyz="0 0 0"/>
    <axis xyz="0 1 0"/>
    <limit effort="35" velocity="20"/>
  </joint>
  <material name="D435i_camera_aluminum">
    <color rgba="0.5 0.5 0.5 1"/>
  </material>
  <!-- camera body, with origin at bottom screw mount -->
  <joint name="D435i_camera_joint" type="fixed">
    <origin rpy="0 -0.5 0" xyz="0.18 0 0"/>
    <parent link="control_box"/>
    <child link="D435i_camera_bottom_screw_frame"/>
  </joint>
  <link name="D435i_camera_bottom_screw_frame"/>
  <joint name="D435i_camera_link_joint" type="fixed">
    <origin rpy="0 0 0" xyz="0 0.0175 0.0125"/>
    <parent link="D435i_camera_bottom_screw_frame"/>
    <child link="D435i_camera_link"/>
  </joint>
  <link name="D435i_camera_link">
    <visual>
      <origin rpy="1.5707963267948966 0 1.5707963267948966" xyz="0.0149 -0.0175 0"/>
      <geometry>
        <!-- <box size="${d435i_cam_width} ${d435i_cam_height} ${d435i_cam_depth}"/> -->
        <mesh filename="package://realsense2_description/meshes/d435.dae"/>
        <!--<mesh filename="package://realsense2_description/meshes/d435/d435.dae"/>-->
      </geometry>
      <material name="D435i_camera_aluminum"/>
    </visual>
    <collision>
      <origin rpy="0 0 0" xyz="0 -0.0175 0"/>
      <geometry>
        <box size="0.02505 0.09 0.025"/>
      </geometry>
    </collision>
    <inertial>
      <!-- The following are not reliable values, and should not be used for modeling -->
      <mass value="0.564"/>
      <origin xyz="0 0 0"/>
      <inertia ixx="0.003881243" ixy="0.0" ixz="0.0" iyy="0.000498940" iyz="0.0" izz="0.003879257"/>
    </inertial>
  </link>
  <!-- camera depth joints and links -->
  <joint name="D435i_camera_depth_joint" type="fixed">
    <origin rpy="0 0 0" xyz="0 0 0"/>
    <parent link="D435i_camera_link"/>
    <child link="D435i_camera_depth_frame"/>
  </joint>
  <link name="D435i_camera_depth_frame"/>
  <joint name="D435i_camera_depth_optical_joint" type="fixed">
    <origin rpy="-1.5707963267948966 0 -1.5707963267948966" xyz="0 0 0"/>
    <parent link="D435i_camera_depth_frame"/>
    <child link="D435i_camera_depth_optical_frame"/>
  </joint>
  <link name="D435i_camera_depth_optical_frame"/>
  <!-- camera left IR joints and links -->
  <joint name="D435i_camera_left_ir_joint" type="fixed">
    <origin rpy="0 0 0" xyz="0 0.0 0"/>
    <parent link="D435i_camera_depth_frame"/>
    <child link="D435i_camera_left_ir_frame"/>
  </joint>
  <link name="D435i_camera_left_ir_frame"/>
  <joint name="D435i_camera_left_ir_optical_joint" type="fixed">
    <origin rpy="-1.5707963267948966 0 -1.5707963267948966" xyz="0 0 0"/>
    <parent link="D435i_camera_left_ir_frame"/>
    <child link="D435i_camera_left_ir_optical_frame"/>
  </joint>
  <link name="D435i_camera_left_ir_optical_frame"/>
  <!-- camera right IR joints and links -->
  <joint name="D435i_camera_right_ir_joint" type="fixed">
    <origin rpy="0 0 0" xyz="0 -0.05 0"/>
    <parent link="D435i_camera_depth_frame"/>
    <child link="D435i_camera_right_ir_frame"/>
  </joint>
  <link name="D435i_camera_right_ir_frame"/>
  <joint name="D435i_camera_right_ir_optical_joint" type="fixed">
    <origin rpy="-1.5707963267948966 0 -1.5707963267948966" xyz="0 0 0"/>
    <parent link="D435i_camera_right_ir_frame"/>
    <child link="D435i_camera_right_ir_optical_frame"/>
  </joint>
  <link name="D435i_camera_right_ir_optical_frame"/>
  <!-- camera color joints and links -->
  <joint name="D435i_camera_color_joint" type="fixed">
    <origin rpy="0 0 0" xyz="0 0.015 0"/>
    <parent link="D435i_camera_depth_frame"/>
    <child link="D435i_camera_color_frame"/>
  </joint>
  <link name="D435i_camera_color_frame"/>
  <joint name="D435i_camera_color_optical_joint" type="fixed">
    <origin rpy="-1.5707963267948966 0 -1.5707963267948966" xyz="0 0 0"/>
    <parent link="D435i_camera_color_frame"/>
    <child link="D435i_camera_color_optical_frame"/>
  </joint>
  <link name="D435i_camera_color_optical_frame"/>
  <!-- camera accel joints and links -->
  <joint name="D435i_camera_accel_joint" type="fixed">
    <origin rpy="0 0 0" xyz="-0.00174 0.00552 0.0176"/>
    <parent link="D435i_camera_link"/>
    <child link="D435i_camera_accel_frame"/>
  </joint>
  <link name="D435i_camera_accel_frame"/>
  <joint name="D435i_camera_accel_optical_joint" type="fixed">
    <origin rpy="-1.5707963267948966 0 -1.5707963267948966" xyz="0 0 0"/>
    <parent link="D435i_camera_accel_frame"/>
    <child link="D435i_camera_accel_optical_frame"/>
  </joint>
  <link name="D435i_camera_accel_optical_frame"/>
  <!-- camera gyro joints and links -->
  <joint name="D435i_camera_gyro_joint" type="fixed">
    <origin rpy="0 0 0" xyz="-0.00174 0.00552 0.0176"/>
    <parent link="D435i_camera_link"/>
    <child link="D435i_camera_gyro_frame"/>
  </joint>
  <link name="D435i_camera_gyro_frame"/>
  <joint name="D435i_camera_gyro_optical_joint" type="fixed">
    <origin rpy="-1.5707963267948966 0 -1.5707963267948966" xyz="0 0 0"/>
    <parent link="D435i_camera_gyro_frame"/>
    <child link="D435i_camera_gyro_optical_frame"/>
  </joint>
  <link name="D435i_camera_gyro_optical_frame"/>
  <gazebo reference="D435i_camera_link">
    <self_collide>0</self_collide>
    <enable_wind>0</enable_wind>
    <kinematic>0</kinematic>
    <!-- <gravity>1</gravity> -->
    <!--<mu>1</mu>-->
    <mu2>1</mu2>
    <fdir1>0 0 0</fdir1>
    <!--<slip1>0</slip1>
      <slip2>0</slip2>-->
    <kp>1e+13</kp>
    <kd>1</kd>
    <!--<max_vel>0.01</max_vel>
      <min_depth>0</min_depth>-->
    <sensor name="D435i_cameracolor" type="camera">
      <camera name="D435i_camera">
        <horizontal_fov>1.2112585008840648</horizontal_fov>
        <image>
          <width>1280</width>
          <height>720</height>
          <format>RGB_INT8</format>
        </image>
        <clip>
          <near>0.1</near>
          <far>100</far>
        </clip>
        <noise>
          <type>gaussian</type>
          <mean>0.0</mean>
          <stddev>0.007</stddev>
        </noise>
      </camera>
      <always_on>1</always_on>
      <update_rate>30</update_rate>
      <visualize>False</visualize>
    </sensor>
    <sensor name="D435i_cameraired1" type="camera">
      <camera name="D435i_camera">
        <horizontal_fov>1.4870205226991688</horizontal_fov>
        <image>
          <width>1280</width>
          <height>720</height>
          <format>L_INT8</format>
        </image>
        <clip>
          <near>0.1</near>
          <far>100</far>
        </clip>
        <noise>
          <type>gaussian</type>
          <mean>0.0</mean>
          <stddev>0.05</stddev>
        </noise>
      </camera>
      <always_on>1</always_on>
      <update_rate>90</update_rate>
      <visualize>false</visualize>
    </sensor>
    <sensor name="D435i_cameraired2" type="camera">
      <camera name="D435i_camera">
        <horizontal_fov>1.4870205226991688</horizontal_fov>
        <image>
          <width>1280</width>
          <height>720</height>
          <format>L_INT8</format>
        </image>
        <clip>
          <near>0.1</near>
          <far>100</far>
        </clip>
        <noise>
          <type>gaussian</type>
          <mean>0.0</mean>
          <stddev>0.05</stddev>
        </noise>
      </camera>
      <always_on>1</always_on>
      <update_rate>90</update_rate>
      <visualize>false</visualize>
    </sensor>
    <sensor name="D435i_cameradepth" type="depth">
      <camera name="D435i_camera">
        <horizontal_fov>1.2112585008840648</horizontal_fov>
        <image>
          <width>1280</width>
          <height>720</height>
        </image>
        <clip>
          <near>0.1</near>
          <far>100</far>
        </clip>
        <noise>
          <type>gaussian</type>
          <mean>0.0</mean>
          <stddev>0.100</stddev>
        </noise>
      </camera>
      <always_on>1</always_on>
      <update_rate>30</update_rate>
      <visualize>false</visualize>
    </sensor>
    <sensor name="D435i_cameraaccel" type="imu">
      <always_on>true</always_on>
      <update_rate>300</update_rate>
      <topic>D435i_camera/accel/sample</topic>
      <plugin filename="librealsense_gazebo_accel_sensor.so" name="D435i/D435i_camera_accel_plugin">
        <topicName>D435i_camera/accel/sample</topicName>
        <bodyName>D435i_camera_link</bodyName>
        <updateRateHZ>300</updateRateHZ>
        <gaussianNoise>0.1</gaussianNoise>
        <xyzOffset>0 0 0</xyzOffset>
        <rpyOffset>0 0 0</rpyOffset>
        <frameName>D435i_camera_accel_optical_frame</frameName>
        <initialOrientationAsReference>false</initialOrientationAsReference>
      </plugin>
      <pose>0 0 0 0 0 0</pose>
    </sensor>
    <sensor name="D435i_cameragyro" type="imu">
      <always_on>true</always_on>
      <update_rate>300</update_rate>
      <topic>D435i_camera/gyro/sample</topic>
      <plugin filename="librealsense_gazebo_gyro_sensor.so" name="D435i/D435i_camera_gyro_plugin">
        <topicName>D435i_camera/gyro/sample</topicName>
        <bodyName>D435i_camera_link</bodyName>
        <updateRateHZ>300</updateRateHZ>
        <gaussianNoise>0.1</gaussianNoise>
        <xyzOffset>0 0 0</xyzOffset>
        <rpyOffset>0 0 0</rpyOffset>
        <frameName>D435i_camera_gyro_optical_frame</frameName>
        <initialOrientationAsReference>false</initialOrientationAsReference>
      </plugin>
    </sensor>
  </gazebo>
  <gazebo>
    <plugin filename="librealsense_gazebo_plugin.so" name="D435i/D435i_camera">
      <prefix>D435i_camera</prefix>
      <!-- Color camera settings -->
      <colorUpdateRate>30</colorUpdateRate>
      <colorTopicName>color/image_raw</colorTopicName>
      <colorOpticalframeName>D435i_camera_color_optical_frame</colorOpticalframeName>
      <colorCameraInfoTopicName>color/camera_info</colorCameraInfoTopicName>
      <!-- Infrared camera settings -->
      <infraredUpdateRate>90</infraredUpdateRate>
      <infrared1TopicName>infra1/image_rect_raw</infrared1TopicName>
      <infrared2TopicName>infra2/image_rect_raw</infrared2TopicName>
      <infrared1CameraInfoTopicName>infra1/camera_info</infrared1CameraInfoTopicName>
      <infrared2CameraInfoTopicName>infra2/camera_info</infrared2CameraInfoTopicName>
      <infrared1OpticalframeName>D435i_camera_left_ir_optical_frame</infrared1OpticalframeName>
      <infrared2OpticalframeName>D435i_camera_right_ir_optical_frame</infrared2OpticalframeName>
      <!-- Depth camera settings -->
      <rangeMinDepth>0.2</rangeMinDepth>
      <rangeMaxDepth>10.0</rangeMaxDepth>
      <depthUpdateRate>30</depthUpdateRate>
      <depthTopicName>aligned_depth_to_color/image_raw</depthTopicName>
      <depthCameraInfoTopicName>aligned_depth_to_color/camera_info</depthCameraInfoTopicName>
      <depthOpticalframeName>D435i_camera_color_optical_frame</depthOpticalframeName>
      <!-- Pointlcloud settings -->
      <pointCloud>True</pointCloud>
      <pointCloudTopicName>depth/color/points</pointCloudTopicName>
      <pointCloudCutoff>0.5</pointCloudCutoff>
    </plugin>
  </gazebo>
  <joint name="mobile_base_joint" type="fixed">
    <!-- mobile base joint -->
    <parent link="control_box"/>
    <child link="relax_arm1_link1"/>
    <origin rpy="3.1415927 0 0" xyz="0 0 0"/>
  </joint>
  <link name="world"/>
  <joint name="world_joint" type="floating">
    <parent link="world"/>
    <child link="base_link"/>
  </joint>
</robot>

