<sdf version='1.7'>
  <model name='relax'>
    <joint name='world_joint' type='fixed'>
      <pose relative_to='__model__'>0 0 0 0 -0 0</pose>
      <parent>world</parent>
      <child>base_link</child>
    </joint>
    <link name='base_link'>
      <pose relative_to='world_joint'>0 0 0 0 -0 0</pose>
      <inertial>
        <pose>0.00099 -0.001335 0.035182 0 -0 0</pose>
        <mass>107.467</mass>
        <inertia>
          <ixx>19.0537</ixx>
          <ixy>-0.00172707</ixy>
          <ixz>-0.0386888</ixz>
          <iyy>19.0565</iyy>
          <iyz>0.0869808</iyz>
          <izz>17.2117</izz>
        </inertia>
      </inertial>
      <collision name='base_link_fixed_joint_lump__mobile_base_link_collision'>
        <pose>0 0 0 0 -0 0</pose>
        <geometry>
          <mesh>
            <scale>0.001 0.001 0.001</scale>
            <uri>model://relax_urdf/meshes/mir_base.stl</uri>
          </mesh>
        </geometry>
      </collision>
      <collision name='base_link_fixed_joint_lump__control_box_collision_1'>
        <pose>0 0 0.375 0 -0 0</pose>
        <geometry>
          <box>
            <size>0.3 0.3 0.15</size>
          </box>
        </geometry>
      </collision>
      <collision name='base_link_fixed_joint_lump__D435i_camera_link_collision_2'>
        <pose>0.174007 0 0.38597 0 -0.5 0</pose>
        <geometry>
          <box>
            <size>0.02505 0.09 0.025</size>
          </box>
        </geometry>
        <surface>
          <contact>
            <ode>
              <kp>1e+13</kp>
              <kd>1</kd>
            </ode>
          </contact>
          <friction>
            <ode>
              <mu2>1</mu2>
              <fdir1>0 0 0</fdir1>
            </ode>
          </friction>
        </surface>
      </collision>
      <collision name='base_link_fixed_joint_lump__relax_link1_collision_3'>
        <pose>0 0 0.375 -3.14159 0 0</pose>
        <geometry>
          <mesh>
            <scale>0.001 0.001 0.001</scale>
            <uri>model://relax_urdf/meshes/mesh_link1.stl</uri>
          </mesh>
        </geometry>
        <surface>
          <contact>
            <ode/>
          </contact>
          <friction>
            <ode/>
          </friction>
        </surface>
      </collision>
      <visual name='base_link_fixed_joint_lump__mobile_base_link_visual'>
        <pose>0 0 0 0 -0 0</pose>
        <geometry>
          <mesh>
            <scale>0.001 0.001 0.001</scale>
            <uri>model://relax_urdf/meshes/mir_base.stl</uri>
          </mesh>
        </geometry>
      </visual>
      <visual name='base_link_fixed_joint_lump__control_box_visual_1'>
        <pose>0 0 0.375 0 -0 0</pose>
        <geometry>
          <box>
            <size>0.3 0.3 0.15</size>
          </box>
        </geometry>
      </visual>
      <visual name='base_link_fixed_joint_lump__D435i_camera_link_visual_2'>
        <pose>0.187083 0 0.393113 1.0708 -0 1.5708</pose>
        <geometry>
          <mesh>
            <scale>1 1 1</scale>
            <uri>model://realsense2_description/meshes/d435.dae</uri>
          </mesh>
        </geometry>
      </visual>
      <visual name='base_link_fixed_joint_lump__relax_link1_visual_3'>
        <pose>0 0 0.375 -3.14159 0 0</pose>
        <geometry>
          <mesh>
            <scale>0.001 0.001 0.001</scale>
            <uri>model://relax_urdf/meshes/mesh_link1.stl</uri>
          </mesh>
        </geometry>
        <material>
          <script>
            <name>Gazebo/Blue</name>
            <uri>file://media/materials/scripts/gazebo.material</uri>
          </script>
        </material>
      </visual>
      <self_collide>0</self_collide>
      <enable_wind>0</enable_wind>
      <kinematic>0</kinematic>
      <sensor name='D435i_cameracolor' type='camera'>
        <camera name='D435i_camera'>
          <horizontal_fov>1.21126</horizontal_fov>
          <image>
            <width>1280</width>
            <height>720</height>
            <format>RGB_INT8</format>
          </image>
          <clip>
            <near>0.1</near>
            <far>100</far>
          </clip>
          <noise>
            <type>gaussian</type>
            <mean>0</mean>
            <stddev>0.007</stddev>
          </noise>
        </camera>
        <always_on>1</always_on>
        <update_rate>30</update_rate>
        <visualize>0</visualize>
        <pose>0.174007 0.0175 0.38597 0 -0.5 0</pose>
      </sensor>
      <sensor name='D435i_cameraired1' type='camera'>
        <camera name='D435i_camera'>
          <horizontal_fov>1.48702</horizontal_fov>
          <image>
            <width>1280</width>
            <height>720</height>
            <format>L_INT8</format>
          </image>
          <clip>
            <near>0.1</near>
            <far>100</far>
          </clip>
          <noise>
            <type>gaussian</type>
            <mean>0</mean>
            <stddev>0.05</stddev>
          </noise>
        </camera>
        <always_on>1</always_on>
        <update_rate>90</update_rate>
        <visualize>0</visualize>
        <pose>0.174007 0.0175 0.38597 0 -0.5 0</pose>
      </sensor>
      <sensor name='D435i_cameraired2' type='camera'>
        <camera name='D435i_camera'>
          <horizontal_fov>1.48702</horizontal_fov>
          <image>
            <width>1280</width>
            <height>720</height>
            <format>L_INT8</format>
          </image>
          <clip>
            <near>0.1</near>
            <far>100</far>
          </clip>
          <noise>
            <type>gaussian</type>
            <mean>0</mean>
            <stddev>0.05</stddev>
          </noise>
        </camera>
        <always_on>1</always_on>
        <update_rate>90</update_rate>
        <visualize>0</visualize>
        <pose>0.174007 0.0175 0.38597 0 -0.5 0</pose>
      </sensor>
      <sensor name='D435i_cameradepth' type='depth'>
        <camera name='D435i_camera'>
          <horizontal_fov>1.21126</horizontal_fov>
          <image>
            <width>1280</width>
            <height>720</height>
          </image>
          <clip>
            <near>0.1</near>
            <far>100</far>
          </clip>
          <noise>
            <type>gaussian</type>
            <mean>0</mean>
            <stddev>0.1</stddev>
          </noise>
        </camera>
        <always_on>1</always_on>
        <update_rate>30</update_rate>
        <visualize>0</visualize>
        <pose>0.174007 0.0175 0.38597 0 -0.5 0</pose>
      </sensor>
      <sensor name='D435i_cameraaccel' type='imu'>
        <always_on>1</always_on>
        <update_rate>300</update_rate>
        <topic>D435i_camera/accel/sample</topic>
        <plugin name='D435i/D435i_camera_accel_plugin' filename='librealsense_gazebo_accel_sensor.so'>
          <topicName>D435i_camera/accel/sample</topicName>
          <bodyName>D435i_camera_link</bodyName>
          <updateRateHZ>300</updateRateHZ>
          <gaussianNoise>0.1</gaussianNoise>
          <xyzOffset>0 0 0</xyzOffset>
          <rpyOffset>0 0 0</rpyOffset>
          <frameName>D435i_camera_accel_optical_frame</frameName>
          <initialOrientationAsReference>0</initialOrientationAsReference>
        </plugin>
        <pose>0.174007 0.0175 0.38597 0 -0.5 0</pose>
      </sensor>
      <sensor name='D435i_cameragyro' type='imu'>
        <always_on>1</always_on>
        <update_rate>300</update_rate>
        <topic>D435i_camera/gyro/sample</topic>
        <plugin name='D435i/D435i_camera_gyro_plugin' filename='librealsense_gazebo_gyro_sensor.so'>
          <topicName>D435i_camera/gyro/sample</topicName>
          <bodyName>D435i_camera_link</bodyName>
          <updateRateHZ>300</updateRateHZ>
          <gaussianNoise>0.1</gaussianNoise>
          <xyzOffset>0 0 0</xyzOffset>
          <rpyOffset>0 0 0</rpyOffset>
          <frameName>D435i_camera_gyro_optical_frame</frameName>
          <initialOrientationAsReference>0</initialOrientationAsReference>
        </plugin>
        <pose>0.174007 0.0175 0.38597 0 -0.5 0</pose>
      </sensor>
    </link>
    <joint name='joint1' type='revolute'>
      <pose relative_to='base_link'>0 -0.13166 0.62466 -3.14159 0 0</pose>
      <parent>base_link</parent>
      <child>relax_link2</child>
      <axis>
        <xyz>0 1 0</xyz>
        <limit>
          <lower>-3.14</lower>
          <upper>3.14</upper>
          <effort>147</effort>
          <velocity>3.86</velocity>
        </limit>
        <dynamics>
          <damping>0.2</damping>
          <friction>10</friction>
          <spring_reference>0</spring_reference>
          <spring_stiffness>0</spring_stiffness>
        </dynamics>
      </axis>
      <physics>
        <provide_feedback>1</provide_feedback>
        <ode>
          <implicit_spring_damper>1</implicit_spring_damper>
          <cfm_damping>1</cfm_damping>
          <limit>
            <cfm>0</cfm>
            <erp>0.2</erp>
          </limit>
          <provide_feedback>1</provide_feedback>
        </ode>
      </physics>
    </joint>
    <link name='relax_link2'>
      <pose relative_to='joint1'>0 0 0 0 -0 0</pose>
      <inertial>
        <pose>0 -0.007172 -0.200007 0 -0 0</pose>
        <mass>1.99897</mass>
        <inertia>
          <ixx>0.0495895</ixx>
          <ixy>-2.38222e-08</ixy>
          <ixz>0.000234769</ixz>
          <iyy>0.0511116</iyy>
          <iyz>7.76985e-07</iyz>
          <izz>0.0040703</izz>
        </inertia>
      </inertial>
      <collision name='relax_link2_collision'>
        <pose>0 0 0 0 -0 0</pose>
        <geometry>
          <mesh>
            <scale>0.001 0.001 0.001</scale>
            <uri>model://relax_urdf/meshes/mesh_link2.stl</uri>
          </mesh>
        </geometry>
        <surface>
          <contact>
            <ode/>
          </contact>
          <friction>
            <ode/>
          </friction>
        </surface>
      </collision>
      <visual name='relax_link2_visual'>
        <pose>0 0 0 0 -0 0</pose>
        <geometry>
          <mesh>
            <scale>0.001 0.001 0.001</scale>
            <uri>model://relax_urdf/meshes/mesh_link2.stl</uri>
          </mesh>
        </geometry>
        <material>
          <script>
            <name>Gazebo/DarkGrey</name>
            <uri>file://media/materials/scripts/gazebo.material</uri>
          </script>
        </material>
      </visual>
    </link>
    <joint name='joint2' type='revolute'>
      <pose relative_to='relax_link2'>0 0 -0.4 0 -0 0</pose>
      <parent>relax_link2</parent>
      <child>relax_link3</child>
      <axis>
        <xyz>0 1 0</xyz>
        <limit>
          <lower>-3.14</lower>
          <upper>3.14</upper>
          <effort>147</effort>
          <velocity>3.86</velocity>
        </limit>
        <dynamics>
          <damping>0.2</damping>
          <friction>10</friction>
          <spring_reference>0</spring_reference>
          <spring_stiffness>0</spring_stiffness>
        </dynamics>
      </axis>
      <physics>
        <provide_feedback>1</provide_feedback>
        <ode>
          <implicit_spring_damper>1</implicit_spring_damper>
          <cfm_damping>1</cfm_damping>
          <limit>
            <cfm>0</cfm>
            <erp>0.2</erp>
          </limit>
          <provide_feedback>1</provide_feedback>
        </ode>
      </physics>
    </joint>
    <link name='relax_link3'>
      <pose relative_to='joint2'>0 0 0 0 -0 0</pose>
      <inertial>
        <pose>-0.002105 -0.106386 -0.074903 0 -0 0</pose>
        <mass>5.88388</mass>
        <inertia>
          <ixx>0.0610436</ixx>
          <ixy>-0.000153409</ixy>
          <ixz>-0.000178332</ixz>
          <iyy>0.0536013</iyy>
          <iyz>-0.0110909</iyz>
          <izz>0.0173808</izz>
        </inertia>
      </inertial>
      <collision name='relax_link3_collision'>
        <pose>0 0 0 0 -0 0</pose>
        <geometry>
          <mesh>
            <scale>0.001 0.001 0.001</scale>
            <uri>model://relax_urdf/meshes/mesh_link3.stl</uri>
          </mesh>
        </geometry>
        <surface>
          <contact>
            <ode/>
          </contact>
          <friction>
            <ode/>
          </friction>
        </surface>
      </collision>
      <visual name='relax_link3_visual'>
        <pose>0 0 0 0 -0 0</pose>
        <geometry>
          <mesh>
            <scale>0.001 0.001 0.001</scale>
            <uri>model://relax_urdf/meshes/mesh_link3.stl</uri>
          </mesh>
        </geometry>
        <material>
          <script>
            <name>Gazebo/Blue</name>
            <uri>file://media/materials/scripts/gazebo.material</uri>
          </script>
        </material>
      </visual>
    </link>
    <joint name='joint3' type='revolute'>
      <pose relative_to='relax_link3'>0 -0.13166 -0.24966 0 -0 0</pose>
      <parent>relax_link3</parent>
      <child>relax_link4</child>
      <axis>
        <xyz>0 0 1</xyz>
        <limit>
          <lower>-3.14</lower>
          <upper>3.14</upper>
          <effort>147</effort>
          <velocity>3.86</velocity>
        </limit>
        <dynamics>
          <damping>0.2</damping>
          <friction>10</friction>
          <spring_reference>0</spring_reference>
          <spring_stiffness>0</spring_stiffness>
        </dynamics>
      </axis>
      <physics>
        <provide_feedback>1</provide_feedback>
        <ode>
          <implicit_spring_damper>1</implicit_spring_damper>
          <cfm_damping>1</cfm_damping>
          <limit>
            <cfm>0</cfm>
            <erp>0.2</erp>
          </limit>
          <provide_feedback>1</provide_feedback>
        </ode>
      </physics>
    </joint>
    <link name='relax_link4'>
      <pose relative_to='joint3'>0 0 0 0 -0 0</pose>
      <inertial>
        <pose>0.000245 -0.001073 -0.049015 0 -0 0</pose>
        <mass>1.39822</mass>
        <inertia>
          <ixx>0.0146673</ixx>
          <ixy>-2.0411e-05</ixy>
          <ixz>-4.47696e-05</ixz>
          <iyy>0.00865986</iyy>
          <iyz>-8.3199e-05</iyz>
          <izz>0.0104509</izz>
        </inertia>
      </inertial>
      <collision name='relax_link4_collision'>
        <pose>0 0 0 0 -0 0</pose>
        <geometry>
          <mesh>
            <scale>0.001 0.001 0.001</scale>
            <uri>model://relax_urdf/meshes/mesh_link4.stl</uri>
          </mesh>
        </geometry>
        <surface>
          <contact>
            <ode/>
          </contact>
          <friction>
            <ode/>
          </friction>
        </surface>
      </collision>
      <visual name='relax_link4_visual'>
        <pose>0 0 0 0 -0 0</pose>
        <geometry>
          <mesh>
            <scale>0.001 0.001 0.001</scale>
            <uri>model://relax_urdf/meshes/mesh_link4.stl</uri>
          </mesh>
        </geometry>
        <material>
          <script>
            <name>Gazebo/Blue</name>
            <uri>file://media/materials/scripts/gazebo.material</uri>
          </script>
        </material>
      </visual>
    </link>
    <joint name='joint4' type='revolute'>
      <pose relative_to='relax_link4'>0 -0.08816 -0.1535 0 0 -3.14159</pose>
      <parent>relax_link4</parent>
      <child>relax_link5</child>
      <axis>
        <xyz>0 1 0</xyz>
        <limit>
          <lower>-3.14</lower>
          <upper>3.14</upper>
          <effort>147</effort>
          <velocity>3.86</velocity>
        </limit>
        <dynamics>
          <damping>0.2</damping>
          <friction>10</friction>
          <spring_reference>0</spring_reference>
          <spring_stiffness>0</spring_stiffness>
        </dynamics>
      </axis>
      <physics>
        <provide_feedback>1</provide_feedback>
        <ode>
          <implicit_spring_damper>1</implicit_spring_damper>
          <cfm_damping>1</cfm_damping>
          <limit>
            <cfm>0</cfm>
            <erp>0.2</erp>
          </limit>
          <provide_feedback>1</provide_feedback>
        </ode>
      </physics>
    </joint>
    <link name='relax_link5'>
      <pose relative_to='joint4'>0 0 0 0 -0 0</pose>
      <inertial>
        <pose>-0.001323 -0.084683 -0.053211 0 -0 0</pose>
        <mass>5.79238</mass>
        <inertia>
          <ixx>0.0551095</ixx>
          <ixy>-0.000140038</ixy>
          <ixz>0.000214707</ixz>
          <iyy>0.0513094</iyy>
          <iyz>-0.00102892</iyz>
          <izz>0.0138048</izz>
        </inertia>
      </inertial>
      <collision name='relax_link5_collision'>
        <pose>0 0 0 0 -0 0</pose>
        <geometry>
          <mesh>
            <scale>0.001 0.001 0.001</scale>
            <uri>model://relax_urdf/meshes/mesh_link5.stl</uri>
          </mesh>
        </geometry>
        <surface>
          <contact>
            <ode/>
          </contact>
          <friction>
            <ode/>
          </friction>
        </surface>
      </collision>
      <visual name='relax_link5_visual'>
        <pose>0 0 0 0 -0 0</pose>
        <geometry>
          <mesh>
            <scale>0.001 0.001 0.001</scale>
            <uri>model://relax_urdf/meshes/mesh_link5.stl</uri>
          </mesh>
        </geometry>
        <material>
          <script>
            <name>Gazebo/Blue</name>
            <uri>file://media/materials/scripts/gazebo.material</uri>
          </script>
        </material>
      </visual>
    </link>
    <joint name='j_left_wheel_yaw' type='revolute'>
      <pose relative_to='base_link'>-0.004487 0.25 0.09 0 -0 0</pose>
      <parent>base_link</parent>
      <child>left_wheel_yaw</child>
      <axis>
        <xyz>0 0 1</xyz>
        <limit>
          <lower>-1</lower>
          <upper>1</upper>
          <effort>35</effort>
          <velocity>20</velocity>
        </limit>
        <dynamics>
          <spring_reference>0</spring_reference>
          <spring_stiffness>0</spring_stiffness>
        </dynamics>
      </axis>
    </joint>
    <link name='left_wheel_yaw'>
      <pose relative_to='j_left_wheel_yaw'>0 0 0 0 -0 0</pose>
      <inertial>
        <pose>0 0 0 0 -0 0</pose>
        <mass>1</mass>
        <inertia>
          <ixx>0.17</ixx>
          <ixy>0</ixy>
          <ixz>0</ixz>
          <iyy>0.17</iyy>
          <iyz>0</iyz>
          <izz>0.17</izz>
        </inertia>
      </inertial>
      <collision name='left_wheel_yaw_collision'>
        <pose>0 0 0 0 -0 0</pose>
        <geometry>
          <box>
            <size>0.001 0.001 0.001</size>
          </box>
        </geometry>
      </collision>
      <visual name='left_wheel_yaw_visual'>
        <pose>0 0 0 0 -0 0</pose>
        <geometry>
          <box>
            <size>0.001 0.001 0.001</size>
          </box>
        </geometry>
      </visual>
    </link>
    <joint name='j_left_wheel_roll' type='revolute'>
      <pose relative_to='left_wheel_yaw'>0 0 0 0 -0 0</pose>
      <parent>left_wheel_yaw</parent>
      <child>left_wheel</child>
      <axis>
        <xyz>0 1 0</xyz>
        <limit>
          <effort>35</effort>
          <velocity>20</velocity>
          <lower>-1e+16</lower>
          <upper>1e+16</upper>
        </limit>
        <dynamics>
          <spring_reference>0</spring_reference>
          <spring_stiffness>0</spring_stiffness>
        </dynamics>
      </axis>
    </joint>
    <link name='left_wheel'>
      <pose relative_to='j_left_wheel_roll'>0 0 0 0 -0 0</pose>
      <inertial>
        <pose>0 0 0 0 -0 0</pose>
        <mass>1</mass>
        <inertia>
          <ixx>0.17</ixx>
          <ixy>0</ixy>
          <ixz>0</ixz>
          <iyy>0.17</iyy>
          <iyz>0</iyz>
          <izz>0.17</izz>
        </inertia>
      </inertial>
      <collision name='left_wheel_collision'>
        <pose>0 0 0 0 -0 0</pose>
        <geometry>
          <mesh>
            <scale>0.001 0.001 0.001</scale>
            <uri>model://relax_urdf/meshes/mir_base.stl</uri>
          </mesh>
        </geometry>
      </collision>
      <visual name='left_wheel_visual'>
        <pose>0 0 0 0 -0 0</pose>
        <geometry>
          <mesh>
            <scale>0.001 0.001 0.001</scale>
            <uri>model://relax_urdf/meshes/mesh_left_wheel.stl</uri>
          </mesh>
        </geometry>
      </visual>
    </link>
    <joint name='j_right_wheel_yaw' type='revolute'>
      <pose relative_to='base_link'>-0.004487 -0.25 0.09 0 -0 0</pose>
      <parent>base_link</parent>
      <child>right_wheel_yaw</child>
      <axis>
        <xyz>0 0 1</xyz>
        <limit>
          <lower>-1</lower>
          <upper>1</upper>
          <effort>35</effort>
          <velocity>20</velocity>
        </limit>
        <dynamics>
          <spring_reference>0</spring_reference>
          <spring_stiffness>0</spring_stiffness>
        </dynamics>
      </axis>
    </joint>
    <link name='right_wheel_yaw'>
      <pose relative_to='j_right_wheel_yaw'>0 0 0 0 -0 0</pose>
      <inertial>
        <pose>0 0 0 0 -0 0</pose>
        <mass>1</mass>
        <inertia>
          <ixx>0.17</ixx>
          <ixy>0</ixy>
          <ixz>0</ixz>
          <iyy>0.17</iyy>
          <iyz>0</iyz>
          <izz>0.17</izz>
        </inertia>
      </inertial>
      <collision name='right_wheel_yaw_collision'>
        <pose>0 0 0 0 -0 0</pose>
        <geometry>
          <box>
            <size>0.001 0.001 0.001</size>
          </box>
        </geometry>
      </collision>
      <visual name='right_wheel_yaw_visual'>
        <pose>0 0 0 0 -0 0</pose>
        <geometry>
          <box>
            <size>0.001 0.001 0.001</size>
          </box>
        </geometry>
      </visual>
    </link>
    <joint name='j_right_wheel_roll' type='revolute'>
      <pose relative_to='right_wheel_yaw'>0 0 0 0 -0 0</pose>
      <parent>right_wheel_yaw</parent>
      <child>right_wheel</child>
      <axis>
        <xyz>0 1 0</xyz>
        <limit>
          <effort>35</effort>
          <velocity>20</velocity>
          <lower>-1e+16</lower>
          <upper>1e+16</upper>
        </limit>
        <dynamics>
          <spring_reference>0</spring_reference>
          <spring_stiffness>0</spring_stiffness>
        </dynamics>
      </axis>
    </joint>
    <link name='right_wheel'>
      <pose relative_to='j_right_wheel_roll'>0 0 0 0 -0 0</pose>
      <inertial>
        <pose>0 0 0 0 -0 0</pose>
        <mass>1</mass>
        <inertia>
          <ixx>0.17</ixx>
          <ixy>0</ixy>
          <ixz>0</ixz>
          <iyy>0.17</iyy>
          <iyz>0</iyz>
          <izz>0.17</izz>
        </inertia>
      </inertial>
      <collision name='right_wheel_collision'>
        <pose>0 0 0 0 -0 0</pose>
        <geometry>
          <mesh>
            <scale>0.001 0.001 0.001</scale>
            <uri>model://relax_urdf/meshes/mir_base.stl</uri>
          </mesh>
        </geometry>
      </collision>
      <visual name='right_wheel_visual'>
        <pose>0 0 0 0 -0 0</pose>
        <geometry>
          <mesh>
            <scale>0.001 0.001 0.001</scale>
            <uri>model://relax_urdf/meshes/mesh_left_wheel.stl</uri>
          </mesh>
        </geometry>
      </visual>
    </link>
    <plugin name='D435i/D435i_camera' filename='librealsense_gazebo_plugin.so'>
      <prefix>D435i_camera</prefix>
      <colorUpdateRate>30</colorUpdateRate>
      <colorTopicName>color/image_raw</colorTopicName>
      <colorOpticalframeName>D435i_camera_color_optical_frame</colorOpticalframeName>
      <colorCameraInfoTopicName>color/camera_info</colorCameraInfoTopicName>
      <infraredUpdateRate>90</infraredUpdateRate>
      <infrared1TopicName>infra1/image_rect_raw</infrared1TopicName>
      <infrared2TopicName>infra2/image_rect_raw</infrared2TopicName>
      <infrared1CameraInfoTopicName>infra1/camera_info</infrared1CameraInfoTopicName>
      <infrared2CameraInfoTopicName>infra2/camera_info</infrared2CameraInfoTopicName>
      <infrared1OpticalframeName>D435i_camera_left_ir_optical_frame</infrared1OpticalframeName>
      <infrared2OpticalframeName>D435i_camera_right_ir_optical_frame</infrared2OpticalframeName>
      <rangeMinDepth>0.2</rangeMinDepth>
      <rangeMaxDepth>10.0</rangeMaxDepth>
      <depthUpdateRate>30</depthUpdateRate>
      <depthTopicName>aligned_depth_to_color/image_raw</depthTopicName>
      <depthCameraInfoTopicName>aligned_depth_to_color/camera_info</depthCameraInfoTopicName>
      <depthOpticalframeName>D435i_camera_color_optical_frame</depthOpticalframeName>
      <pointCloud>1</pointCloud>
      <pointCloudTopicName>depth/color/points</pointCloudTopicName>
      <pointCloudCutoff>0.5</pointCloudCutoff>
    </plugin>
    <static>0</static>
    <plugin name='xbot2_link_state_sensor' filename='libxbot2_gz_link_state_sensor.so'>
      <links>
        <link name='base_link'/>
        <link name='left_wheel'/>
      </links>
    </plugin>
    <plugin name='xbot2_joint_driver' filename='libxbot2_gz_joint_server.so'>
      <pid>
        <gain d='5' name='lowpwr_mot' p='50'/>
        <gain d='5' name='small_mot' p='250'/>
        <gain d='10' name='medium_mot' p='1000'/>
        <gain d='10' name='big_mot' p='3000'/>
        <gain d='10' name='wheel_mot' p='0'/>
        <pid name='j_left_wheel_roll' profile='wheel_mot'/>
        <pid name='j_right_wheel_roll' profile='wheel_mot'/>
        <pid name='joint1' profile='medium_mot'/>
        <pid name='joint2' profile='medium_mot'/>
        <pid name='joint3' profile='medium_mot'/>
        <pid name='joint4' profile='small_mot'/>
        <pid name='joint5' profile='small_mot'/>
      </pid>
    </plugin>
  </model>
</sdf>
